[DEBUG] 2020-11-13 18:30:17,296 | /home/anil/medley/apps/frappe/frappe/utils/scheduler.py:
Site: ordermedicines
Queued events for site ordermedicines
[DEBUG] 2020-11-13 18:31:17,389 | /home/anil/medley/apps/frappe/frappe/utils/scheduler.py:
Site: ordermedicine
Access denied for site ordermedicine
[DEBUG] 2020-11-13 18:31:17,596 | /home/anil/medley/apps/frappe/frappe/utils/scheduler.py:
Site: ordermedicines
Queued events for site ordermedicines
[DEBUG] 2020-11-13 18:32:17,668 | /home/anil/medley/apps/frappe/frappe/utils/scheduler.py:
Site: ordermedicine
Access denied for site ordermedicine
[DEBUG] 2020-11-13 18:32:17,795 | /home/anil/medley/apps/frappe/frappe/utils/scheduler.py:
Site: ordermedicines
Queued events for site ordermedicines
[DEBUG] 2020-11-13 18:33:17,872 | /home/anil/medley/apps/frappe/frappe/utils/scheduler.py:
Site: ordermedicine
Access denied for site ordermedicine
[DEBUG] 2020-11-13 18:33:18,000 | /home/anil/medley/apps/frappe/frappe/utils/scheduler.py:
Site: ordermedicines
Queued events for site ordermedicines
[DEBUG] 2020-11-13 18:34:18,085 | /home/anil/medley/apps/frappe/frappe/utils/scheduler.py:
Site: ordermedicine
Access denied for site ordermedicine
[DEBUG] 2020-11-13 18:34:18,231 | /home/anil/medley/apps/frappe/frappe/utils/scheduler.py:
Site: ordermedicines
Queued events for site ordermedicines
[DEBUG] 2020-11-13 18:35:18,303 | /home/anil/medley/apps/frappe/frappe/utils/scheduler.py:
Site: ordermedicine
Access denied for site ordermedicine
[DEBUG] 2020-11-13 18:35:18,451 | /home/anil/medley/apps/frappe/frappe/utils/scheduler.py:
Site: ordermedicines
Queued events for site ordermedicines
[DEBUG] 2020-11-13 18:36:18,525 | /home/anil/medley/apps/frappe/frappe/utils/scheduler.py:
Site: ordermedicine
Access denied for site ordermedicine
[DEBUG] 2020-11-13 18:36:18,714 | /home/anil/medley/apps/frappe/frappe/utils/scheduler.py:
Site: ordermedicines
Queued events for site ordermedicines
[DEBUG] 2020-11-13 18:37:18,796 | /home/anil/medley/apps/frappe/frappe/utils/scheduler.py:
Site: ordermedicine
Access denied for site ordermedicine
[DEBUG] 2020-11-13 18:37:18,939 | /home/anil/medley/apps/frappe/frappe/utils/scheduler.py:
Site: ordermedicines
Queued events for site ordermedicines
[DEBUG] 2020-11-13 18:38:19,013 | /home/anil/medley/apps/frappe/frappe/utils/scheduler.py:
Site: ordermedicine
Access denied for site ordermedicine
[DEBUG] 2020-11-13 18:38:19,111 | /home/anil/medley/apps/frappe/frappe/utils/scheduler.py:
Site: ordermedicines
Queued events for site ordermedicines
[DEBUG] 2020-11-13 18:39:19,177 | /home/anil/medley/apps/frappe/frappe/utils/scheduler.py:
Site: ordermedicine
Access denied for site ordermedicine
[DEBUG] 2020-11-13 18:39:19,547 | /home/anil/medley/apps/frappe/frappe/utils/scheduler.py:
Site: ordermedicines
Queued events for site ordermedicines
[DEBUG] 2020-11-13 18:40:19,626 | /home/anil/medley/apps/frappe/frappe/utils/scheduler.py:
Site: ordermedicine
Access denied for site ordermedicine
[DEBUG] 2020-11-13 18:40:19,794 | /home/anil/medley/apps/frappe/frappe/utils/scheduler.py:
Site: ordermedicines
Queued events for site ordermedicines
[DEBUG] 2020-11-13 18:41:19,869 | /home/anil/medley/apps/frappe/frappe/utils/scheduler.py:
Site: ordermedicine
Access denied for site ordermedicine
[DEBUG] 2020-11-13 18:41:20,033 | /home/anil/medley/apps/frappe/frappe/utils/scheduler.py:
Site: ordermedicines
Queued events for site ordermedicines
[DEBUG] 2020-11-13 18:42:20,111 | /home/anil/medley/apps/frappe/frappe/utils/scheduler.py:
Site: ordermedicine
Access denied for site ordermedicine
[DEBUG] 2020-11-13 18:42:20,236 | /home/anil/medley/apps/frappe/frappe/utils/scheduler.py:
Site: ordermedicines
Queued events for site ordermedicines
[DEBUG] 2020-11-13 18:43:20,302 | /home/anil/medley/apps/frappe/frappe/utils/scheduler.py:
Site: ordermedicine
Access denied for site ordermedicine
[DEBUG] 2020-11-13 18:43:20,417 | /home/anil/medley/apps/frappe/frappe/utils/scheduler.py:
Site: ordermedicines
Queued events for site ordermedicines
[DEBUG] 2020-11-13 18:44:20,486 | /home/anil/medley/apps/frappe/frappe/utils/scheduler.py:
Site: ordermedicine
Access denied for site ordermedicine
[DEBUG] 2020-11-13 18:44:20,662 | /home/anil/medley/apps/frappe/frappe/utils/scheduler.py:
Site: ordermedicines
Queued events for site ordermedicines
[DEBUG] 2020-11-13 18:45:20,742 | /home/anil/medley/apps/frappe/frappe/utils/scheduler.py:
Site: ordermedicine
Access denied for site ordermedicine
[DEBUG] 2020-11-13 18:45:20,880 | /home/anil/medley/apps/frappe/frappe/utils/scheduler.py:
Site: ordermedicines
Queued events for site ordermedicines
[DEBUG] 2020-11-13 18:46:20,961 | /home/anil/medley/apps/frappe/frappe/utils/scheduler.py:
Site: ordermedicine
Access denied for site ordermedicine
[DEBUG] 2020-11-13 18:46:21,125 | /home/anil/medley/apps/frappe/frappe/utils/scheduler.py:
Site: ordermedicines
Queued events for site ordermedicines
[DEBUG] 2020-11-13 18:47:21,200 | /home/anil/medley/apps/frappe/frappe/utils/scheduler.py:
Site: ordermedicine
Access denied for site ordermedicine
[DEBUG] 2020-11-13 18:47:21,386 | /home/anil/medley/apps/frappe/frappe/utils/scheduler.py:
Site: ordermedicines
Queued events for site ordermedicines
[DEBUG] 2020-11-13 18:48:21,450 | /home/anil/medley/apps/frappe/frappe/utils/scheduler.py:
Site: ordermedicine
Access denied for site ordermedicine
[DEBUG] 2020-11-13 18:48:21,669 | /home/anil/medley/apps/frappe/frappe/utils/scheduler.py:
Site: ordermedicines
Queued events for site ordermedicines
[DEBUG] 2020-11-13 18:49:21,738 | /home/anil/medley/apps/frappe/frappe/utils/scheduler.py:
Site: ordermedicine
Access denied for site ordermedicine
[DEBUG] 2020-11-13 18:49:21,889 | /home/anil/medley/apps/frappe/frappe/utils/scheduler.py:
Site: ordermedicines
Queued events for site ordermedicines
[DEBUG] 2020-11-13 18:50:21,954 | /home/anil/medley/apps/frappe/frappe/utils/scheduler.py:
Site: ordermedicine
Access denied for site ordermedicine
[DEBUG] 2020-11-13 18:50:22,089 | /home/anil/medley/apps/frappe/frappe/utils/scheduler.py:
Site: ordermedicines
Queued events for site ordermedicines
[DEBUG] 2020-11-13 18:51:22,154 | /home/anil/medley/apps/frappe/frappe/utils/scheduler.py:
Site: ordermedicine
Access denied for site ordermedicine
[DEBUG] 2020-11-13 18:51:22,301 | /home/anil/medley/apps/frappe/frappe/utils/scheduler.py:
Site: ordermedicines
Queued events for site ordermedicines
[DEBUG] 2020-11-13 18:52:22,368 | /home/anil/medley/apps/frappe/frappe/utils/scheduler.py:
Site: ordermedicine
Access denied for site ordermedicine
[DEBUG] 2020-11-13 18:52:22,547 | /home/anil/medley/apps/frappe/frappe/utils/scheduler.py:
Site: ordermedicines
Queued events for site ordermedicines
[DEBUG] 2020-11-13 18:53:22,609 | /home/anil/medley/apps/frappe/frappe/utils/scheduler.py:
Site: ordermedicine
Access denied for site ordermedicine
[DEBUG] 2020-11-13 18:53:22,741 | /home/anil/medley/apps/frappe/frappe/utils/scheduler.py:
Site: ordermedicines
Queued events for site ordermedicines
[DEBUG] 2020-11-13 18:54:22,808 | /home/anil/medley/apps/frappe/frappe/utils/scheduler.py:
Site: ordermedicine
Access denied for site ordermedicine
[DEBUG] 2020-11-13 18:54:23,002 | /home/anil/medley/apps/frappe/frappe/utils/scheduler.py:
Site: ordermedicines
Queued events for site ordermedicines
[DEBUG] 2020-11-13 18:55:23,071 | /home/anil/medley/apps/frappe/frappe/utils/scheduler.py:
Site: ordermedicine
Access denied for site ordermedicine
[DEBUG] 2020-11-13 18:55:23,225 | /home/anil/medley/apps/frappe/frappe/utils/scheduler.py:
Site: ordermedicines
Queued events for site ordermedicines
[DEBUG] 2020-11-13 18:56:23,290 | /home/anil/medley/apps/frappe/frappe/utils/scheduler.py:
Site: ordermedicine
Access denied for site ordermedicine
[DEBUG] 2020-11-13 18:56:23,484 | /home/anil/medley/apps/frappe/frappe/utils/scheduler.py:
Site: ordermedicines
Queued events for site ordermedicines
[DEBUG] 2020-11-13 18:57:23,558 | /home/anil/medley/apps/frappe/frappe/utils/scheduler.py:
Site: ordermedicine
Access denied for site ordermedicine
[DEBUG] 2020-11-13 18:57:23,730 | /home/anil/medley/apps/frappe/frappe/utils/scheduler.py:
Site: ordermedicines
Queued events for site ordermedicines
[DEBUG] 2020-11-13 18:58:23,801 | /home/anil/medley/apps/frappe/frappe/utils/scheduler.py:
Site: ordermedicine
Access denied for site ordermedicine
[DEBUG] 2020-11-13 18:58:23,945 | /home/anil/medley/apps/frappe/frappe/utils/scheduler.py:
Site: ordermedicines
Queued events for site ordermedicines
[DEBUG] 2020-11-13 18:59:24,016 | /home/anil/medley/apps/frappe/frappe/utils/scheduler.py:
Site: ordermedicine
Access denied for site ordermedicine
[DEBUG] 2020-11-13 18:59:24,165 | /home/anil/medley/apps/frappe/frappe/utils/scheduler.py:
Site: ordermedicines
Queued events for site ordermedicines
[DEBUG] 2020-11-13 19:00:24,230 | /home/anil/medley/apps/frappe/frappe/utils/scheduler.py:
Site: ordermedicine
Access denied for site ordermedicine
[DEBUG] 2020-11-13 19:00:24,438 | /home/anil/medley/apps/frappe/frappe/utils/scheduler.py:
Site: ordermedicines
Queued events for site ordermedicines
[DEBUG] 2020-11-13 19:01:24,511 | /home/anil/medley/apps/frappe/frappe/utils/scheduler.py:
Site: ordermedicine
Access denied for site ordermedicine
[DEBUG] 2020-11-13 19:01:24,656 | /home/anil/medley/apps/frappe/frappe/utils/scheduler.py:
Site: ordermedicines
Queued events for site ordermedicines
[DEBUG] 2020-11-13 19:02:24,733 | /home/anil/medley/apps/frappe/frappe/utils/scheduler.py:
Site: ordermedicine
Access denied for site ordermedicine
[DEBUG] 2020-11-13 19:02:24,899 | /home/anil/medley/apps/frappe/frappe/utils/scheduler.py:
Site: ordermedicines
Queued events for site ordermedicines
[DEBUG] 2020-11-13 19:03:24,971 | /home/anil/medley/apps/frappe/frappe/utils/scheduler.py:
Site: ordermedicine
Access denied for site ordermedicine
[DEBUG] 2020-11-13 19:03:25,121 | /home/anil/medley/apps/frappe/frappe/utils/scheduler.py:
Site: ordermedicines
Queued events for site ordermedicines
[DEBUG] 2020-11-13 19:04:25,195 | /home/anil/medley/apps/frappe/frappe/utils/scheduler.py:
Site: ordermedicine
Access denied for site ordermedicine
[DEBUG] 2020-11-13 19:04:25,443 | /home/anil/medley/apps/frappe/frappe/utils/scheduler.py:
Site: ordermedicines
Queued events for site ordermedicines
[DEBUG] 2020-11-13 19:05:25,517 | /home/anil/medley/apps/frappe/frappe/utils/scheduler.py:
Site: ordermedicine
Access denied for site ordermedicine
[DEBUG] 2020-11-13 19:05:25,636 | /home/anil/medley/apps/frappe/frappe/utils/scheduler.py:
Site: ordermedicines
Queued events for site ordermedicines
[DEBUG] 2020-11-13 19:06:25,714 | /home/anil/medley/apps/frappe/frappe/utils/scheduler.py:
Site: ordermedicine
Access denied for site ordermedicine
[DEBUG] 2020-11-13 19:06:25,855 | /home/anil/medley/apps/frappe/frappe/utils/scheduler.py:
Site: ordermedicines
Queued events for site ordermedicines
[DEBUG] 2020-11-13 19:07:25,938 | /home/anil/medley/apps/frappe/frappe/utils/scheduler.py:
Site: ordermedicine
Access denied for site ordermedicine
[DEBUG] 2020-11-13 19:07:26,086 | /home/anil/medley/apps/frappe/frappe/utils/scheduler.py:
Site: ordermedicines
Queued events for site ordermedicines
[DEBUG] 2020-11-13 19:08:26,167 | /home/anil/medley/apps/frappe/frappe/utils/scheduler.py:
Site: ordermedicine
Access denied for site ordermedicine
[DEBUG] 2020-11-13 19:08:26,428 | /home/anil/medley/apps/frappe/frappe/utils/scheduler.py:
Site: ordermedicines
Queued events for site ordermedicines
[DEBUG] 2020-11-13 19:09:26,502 | /home/anil/medley/apps/frappe/frappe/utils/scheduler.py:
Site: ordermedicine
Access denied for site ordermedicine
[DEBUG] 2020-11-13 19:09:26,669 | /home/anil/medley/apps/frappe/frappe/utils/scheduler.py:
Site: ordermedicines
Queued events for site ordermedicines
[DEBUG] 2020-11-13 19:10:26,745 | /home/anil/medley/apps/frappe/frappe/utils/scheduler.py:
Site: ordermedicine
Access denied for site ordermedicine
[DEBUG] 2020-11-13 19:10:26,877 | /home/anil/medley/apps/frappe/frappe/utils/scheduler.py:
Site: ordermedicines
Queued events for site ordermedicines
[DEBUG] 2020-11-13 19:11:26,949 | /home/anil/medley/apps/frappe/frappe/utils/scheduler.py:
Site: ordermedicine
Access denied for site ordermedicine
[DEBUG] 2020-11-13 19:11:27,095 | /home/anil/medley/apps/frappe/frappe/utils/scheduler.py:
Site: ordermedicines
Queued events for site ordermedicines
[DEBUG] 2020-11-13 19:12:27,165 | /home/anil/medley/apps/frappe/frappe/utils/scheduler.py:
Site: ordermedicine
Access denied for site ordermedicine
[DEBUG] 2020-11-13 19:12:27,365 | /home/anil/medley/apps/frappe/frappe/utils/scheduler.py:
Site: ordermedicines
Queued events for site ordermedicines
[DEBUG] 2020-11-13 19:13:27,443 | /home/anil/medley/apps/frappe/frappe/utils/scheduler.py:
Site: ordermedicine
Access denied for site ordermedicine
[DEBUG] 2020-11-13 19:13:27,598 | /home/anil/medley/apps/frappe/frappe/utils/scheduler.py:
Site: ordermedicines
Queued events for site ordermedicines
[ERROR] 2020-11-13 19:14:23,039 | /home/anil/medley/apps/frappe/frappe/app.py:
Site: ordermedicines
Form Dict: {
 "cmd": "erpnext.selling.page.point_of_sale.point_of_sale.get_items",
 "item_group": "All Item Groups",
 "page_length": "40",
 "search_value": "",
 "start": "0"
}
Request Error
Traceback (most recent call last):
  File "/home/anil/medley/apps/frappe/frappe/app.py", line 64, in application
    response = frappe.api.handle()
  File "/home/anil/medley/apps/frappe/frappe/api.py", line 59, in handle
    return frappe.handler.handle()
  File "/home/anil/medley/apps/frappe/frappe/handler.py", line 24, in handle
    data = execute_cmd(cmd)
  File "/home/anil/medley/apps/frappe/frappe/handler.py", line 64, in execute_cmd
    return frappe.call(method, **frappe.form_dict)
  File "/home/anil/medley/apps/frappe/frappe/__init__.py", line 1064, in call
    return fn(*args, **newargs)
TypeError: get_items() missing 1 required positional argument: 'price_list'
[ERROR] 2020-11-13 19:14:23,270 | /home/anil/medley/apps/frappe/frappe/utils/error.py:
New Exception collected with id: 2020-11-13 19:14:23.043452-127.0.0.1-7b7
[ERROR] 2020-11-13 19:14:23,936 | /home/anil/medley/apps/frappe/frappe/app.py:
Site: ordermedicines
Form Dict: {
 "cmd": "erpnext.regional.india.utils.get_regional_address_details",
 "company": "Medley",
 "doctype": "Sales Invoice",
 "party_details": "{\"shipping_address\":\"\",\"shipping_address_name\":\"\",\"customer_address\":\"\",\"customer\":\"\"}",
 "return_taxes": "1"
}
Request Error
Traceback (most recent call last):
  File "/home/anil/medley/apps/frappe/frappe/app.py", line 64, in application
    response = frappe.api.handle()
  File "/home/anil/medley/apps/frappe/frappe/api.py", line 59, in handle
    return frappe.handler.handle()
  File "/home/anil/medley/apps/frappe/frappe/handler.py", line 24, in handle
    data = execute_cmd(cmd)
  File "/home/anil/medley/apps/frappe/frappe/handler.py", line 64, in execute_cmd
    return frappe.call(method, **frappe.form_dict)
  File "/home/anil/medley/apps/frappe/frappe/__init__.py", line 1064, in call
    return fn(*args, **newargs)
  File "/home/anil/medley/apps/erpnext/erpnext/regional/india/utils.py", line 162, in get_regional_address_details
    get_tax_template_for_sez(party_details, master_doctype, company, 'Customer')
  File "/home/anil/medley/apps/erpnext/erpnext/regional/india/utils.py", line 229, in get_tax_template_for_sez
    gst_details = frappe.db.get_value(party_type, {'name': party_details.get(frappe.scrub(party_type))},
  File "/home/anil/medley/apps/frappe/frappe/database/database.py", line 400, in get_value
    ret = self.get_values(doctype, filters, fieldname, ignore, as_dict, debug,
  File "/home/anil/medley/apps/frappe/frappe/database/database.py", line 445, in get_values
    out = self._get_values_from_table(fields, filters, doctype, as_dict, debug, order_by, update)
  File "/home/anil/medley/apps/frappe/frappe/database/database.py", line 590, in _get_values_from_table
    r = self.sql("select {0} from `tab{1}` {2} {3} {4}"
  File "/home/anil/medley/apps/frappe/frappe/database/database.py", line 156, in sql
    self._cursor.execute(query, values)
  File "/home/anil/medley/env/lib/python3.8/site-packages/pymysql/cursors.py", line 170, in execute
    result = self._query(query)
  File "/home/anil/medley/env/lib/python3.8/site-packages/pymysql/cursors.py", line 328, in _query
    conn.query(q)
  File "/home/anil/medley/env/lib/python3.8/site-packages/pymysql/connections.py", line 517, in query
    self._affected_rows = self._read_query_result(unbuffered=unbuffered)
  File "/home/anil/medley/env/lib/python3.8/site-packages/pymysql/connections.py", line 732, in _read_query_result
    result.read()
  File "/home/anil/medley/env/lib/python3.8/site-packages/pymysql/connections.py", line 1075, in read
    first_packet = self.connection._read_packet()
  File "/home/anil/medley/env/lib/python3.8/site-packages/pymysql/connections.py", line 684, in _read_packet
    packet.check_error()
  File "/home/anil/medley/env/lib/python3.8/site-packages/pymysql/protocol.py", line 220, in check_error
    err.raise_mysql_exception(self._data)
  File "/home/anil/medley/env/lib/python3.8/site-packages/pymysql/err.py", line 109, in raise_mysql_exception
    raise errorclass(errno, errval)
pymysql.err.InternalError: (1054, "Unknown column 'gst_category' in 'field list'")
[ERROR] 2020-11-13 19:14:23,967 | /home/anil/medley/apps/frappe/frappe/utils/error.py:
New Exception collected with id: 2020-11-13 19:14:23.937218-127.0.0.1-96f
[DEBUG] 2020-11-13 19:14:27,671 | /home/anil/medley/apps/frappe/frappe/utils/scheduler.py:
Site: ordermedicine
Access denied for site ordermedicine
[DEBUG] 2020-11-13 19:14:27,806 | /home/anil/medley/apps/frappe/frappe/utils/scheduler.py:
Site: ordermedicines
Queued events for site ordermedicines
[DEBUG] 2020-11-13 19:15:27,879 | /home/anil/medley/apps/frappe/frappe/utils/scheduler.py:
Site: ordermedicine
Access denied for site ordermedicine
[DEBUG] 2020-11-13 19:15:28,060 | /home/anil/medley/apps/frappe/frappe/utils/scheduler.py:
Site: ordermedicines
Queued events for site ordermedicines
[DEBUG] 2020-11-13 19:16:28,133 | /home/anil/medley/apps/frappe/frappe/utils/scheduler.py:
Site: ordermedicine
Access denied for site ordermedicine
[DEBUG] 2020-11-13 19:16:28,298 | /home/anil/medley/apps/frappe/frappe/utils/scheduler.py:
Site: ordermedicines
Queued events for site ordermedicines
[ERROR] 2020-11-13 19:19:01,649 | /home/anil/medley/apps/frappe/frappe/app.py:
Site: ordermedicines
Form Dict: {
 "cmd": "frappe.realtime.get_user_info"
}
Request Error
Traceback (most recent call last):
  File "/home/anil/medley/apps/frappe/frappe/app.py", line 64, in application
    response = frappe.api.handle()
  File "/home/anil/medley/apps/frappe/frappe/api.py", line 59, in handle
    return frappe.handler.handle()
  File "/home/anil/medley/apps/frappe/frappe/handler.py", line 24, in handle
    data = execute_cmd(cmd)
  File "/home/anil/medley/apps/frappe/frappe/handler.py", line 64, in execute_cmd
    return frappe.call(method, **frappe.form_dict)
  File "/home/anil/medley/apps/frappe/frappe/__init__.py", line 1064, in call
    return fn(*args, **newargs)
TypeError: get_user_info() missing 1 required positional argument: 'sid'
[ERROR] 2020-11-13 19:19:01,650 | /home/anil/medley/apps/frappe/frappe/app.py:
Site: ordermedicines
Form Dict: {
 "cmd": "frappe.realtime.get_user_info"
}
Request Error
Traceback (most recent call last):
  File "/home/anil/medley/apps/frappe/frappe/app.py", line 64, in application
    response = frappe.api.handle()
  File "/home/anil/medley/apps/frappe/frappe/api.py", line 59, in handle
    return frappe.handler.handle()
  File "/home/anil/medley/apps/frappe/frappe/handler.py", line 24, in handle
    data = execute_cmd(cmd)
  File "/home/anil/medley/apps/frappe/frappe/handler.py", line 64, in execute_cmd
    return frappe.call(method, **frappe.form_dict)
  File "/home/anil/medley/apps/frappe/frappe/__init__.py", line 1064, in call
    return fn(*args, **newargs)
TypeError: get_user_info() missing 1 required positional argument: 'sid'
[ERROR] 2020-11-13 19:19:01,885 | /home/anil/medley/apps/frappe/frappe/utils/error.py:
New Exception collected with id: 2020-11-13 19:19:01.676829-127.0.0.1-09c
[ERROR] 2020-11-13 19:19:01,886 | /home/anil/medley/apps/frappe/frappe/utils/error.py:
New Exception collected with id: 2020-11-13 19:19:01.677396-127.0.0.1-d7e
[DEBUG] 2020-11-13 19:19:58,612 | /home/anil/medley/apps/frappe/frappe/utils/scheduler.py:
Site: ordermedicine
Access denied for site ordermedicine
[DEBUG] 2020-11-13 19:19:59,111 | /home/anil/medley/apps/frappe/frappe/utils/scheduler.py:
Site: ordermedicines
Queued events for site ordermedicines
[DEBUG] 2020-11-13 19:20:59,190 | /home/anil/medley/apps/frappe/frappe/utils/scheduler.py:
Site: ordermedicine
Access denied for site ordermedicine
[DEBUG] 2020-11-13 19:20:59,392 | /home/anil/medley/apps/frappe/frappe/utils/scheduler.py:
Site: ordermedicines
Queued events for site ordermedicines
[DEBUG] 2020-11-13 19:21:59,459 | /home/anil/medley/apps/frappe/frappe/utils/scheduler.py:
Site: ordermedicine
Access denied for site ordermedicine
[DEBUG] 2020-11-13 19:21:59,811 | /home/anil/medley/apps/frappe/frappe/utils/scheduler.py:
Site: ordermedicines
Queued events for site ordermedicines
[DEBUG] 2020-11-13 19:22:59,921 | /home/anil/medley/apps/frappe/frappe/utils/scheduler.py:
Site: ordermedicine
Access denied for site ordermedicine
[DEBUG] 2020-11-13 19:23:00,079 | /home/anil/medley/apps/frappe/frappe/utils/scheduler.py:
Site: ordermedicines
Queued events for site ordermedicines
[ERROR] 2020-11-13 19:23:54,029 | /home/anil/medley/apps/frappe/frappe/app.py:
Site: ordermedicines
Form Dict: {
 "cmd": "erpnext.selling.page.point_of_sale.point_of_sale.get_items",
 "item_group": "All Item Groups",
 "page_length": "40",
 "search_value": "",
 "start": "0"
}
Request Error
Traceback (most recent call last):
  File "/home/anil/medley/apps/frappe/frappe/app.py", line 64, in application
    response = frappe.api.handle()
  File "/home/anil/medley/apps/frappe/frappe/api.py", line 59, in handle
    return frappe.handler.handle()
  File "/home/anil/medley/apps/frappe/frappe/handler.py", line 24, in handle
    data = execute_cmd(cmd)
  File "/home/anil/medley/apps/frappe/frappe/handler.py", line 64, in execute_cmd
    return frappe.call(method, **frappe.form_dict)
  File "/home/anil/medley/apps/frappe/frappe/__init__.py", line 1064, in call
    return fn(*args, **newargs)
TypeError: get_items() missing 1 required positional argument: 'price_list'
[ERROR] 2020-11-13 19:23:54,035 | /home/anil/medley/apps/frappe/frappe/utils/error.py:
New Exception collected with id: 2020-11-13 19:23:54.032614-127.0.0.1-435
[ERROR] 2020-11-13 19:23:54,960 | /home/anil/medley/apps/frappe/frappe/app.py:
Site: ordermedicines
Form Dict: {
 "cmd": "erpnext.regional.india.utils.get_regional_address_details",
 "company": "Medley",
 "doctype": "Sales Invoice",
 "party_details": "{\"shipping_address\":\"\",\"shipping_address_name\":\"\",\"customer_address\":\"\",\"customer\":\"\"}",
 "return_taxes": "1"
}
Request Error
Traceback (most recent call last):
  File "/home/anil/medley/apps/frappe/frappe/app.py", line 64, in application
    response = frappe.api.handle()
  File "/home/anil/medley/apps/frappe/frappe/api.py", line 59, in handle
    return frappe.handler.handle()
  File "/home/anil/medley/apps/frappe/frappe/handler.py", line 24, in handle
    data = execute_cmd(cmd)
  File "/home/anil/medley/apps/frappe/frappe/handler.py", line 64, in execute_cmd
    return frappe.call(method, **frappe.form_dict)
  File "/home/anil/medley/apps/frappe/frappe/__init__.py", line 1064, in call
    return fn(*args, **newargs)
  File "/home/anil/medley/apps/erpnext/erpnext/regional/india/utils.py", line 162, in get_regional_address_details
    get_tax_template_for_sez(party_details, master_doctype, company, 'Customer')
  File "/home/anil/medley/apps/erpnext/erpnext/regional/india/utils.py", line 229, in get_tax_template_for_sez
    gst_details = frappe.db.get_value(party_type, {'name': party_details.get(frappe.scrub(party_type))},
  File "/home/anil/medley/apps/frappe/frappe/database/database.py", line 400, in get_value
    ret = self.get_values(doctype, filters, fieldname, ignore, as_dict, debug,
  File "/home/anil/medley/apps/frappe/frappe/database/database.py", line 445, in get_values
    out = self._get_values_from_table(fields, filters, doctype, as_dict, debug, order_by, update)
  File "/home/anil/medley/apps/frappe/frappe/database/database.py", line 590, in _get_values_from_table
    r = self.sql("select {0} from `tab{1}` {2} {3} {4}"
  File "/home/anil/medley/apps/frappe/frappe/database/database.py", line 156, in sql
    self._cursor.execute(query, values)
  File "/home/anil/medley/env/lib/python3.8/site-packages/pymysql/cursors.py", line 170, in execute
    result = self._query(query)
  File "/home/anil/medley/env/lib/python3.8/site-packages/pymysql/cursors.py", line 328, in _query
    conn.query(q)
  File "/home/anil/medley/env/lib/python3.8/site-packages/pymysql/connections.py", line 517, in query
    self._affected_rows = self._read_query_result(unbuffered=unbuffered)
  File "/home/anil/medley/env/lib/python3.8/site-packages/pymysql/connections.py", line 732, in _read_query_result
    result.read()
  File "/home/anil/medley/env/lib/python3.8/site-packages/pymysql/connections.py", line 1075, in read
    first_packet = self.connection._read_packet()
  File "/home/anil/medley/env/lib/python3.8/site-packages/pymysql/connections.py", line 684, in _read_packet
    packet.check_error()
  File "/home/anil/medley/env/lib/python3.8/site-packages/pymysql/protocol.py", line 220, in check_error
    err.raise_mysql_exception(self._data)
  File "/home/anil/medley/env/lib/python3.8/site-packages/pymysql/err.py", line 109, in raise_mysql_exception
    raise errorclass(errno, errval)
pymysql.err.InternalError: (1054, "Unknown column 'gst_category' in 'field list'")
[ERROR] 2020-11-13 19:23:55,058 | /home/anil/medley/apps/frappe/frappe/utils/error.py:
New Exception collected with id: 2020-11-13 19:23:54.961731-127.0.0.1-993
[DEBUG] 2020-11-13 19:24:00,151 | /home/anil/medley/apps/frappe/frappe/utils/scheduler.py:
Site: ordermedicine
Access denied for site ordermedicine
[DEBUG] 2020-11-13 19:24:00,345 | /home/anil/medley/apps/frappe/frappe/utils/scheduler.py:
Site: ordermedicines
Queued events for site ordermedicines
[DEBUG] 2020-11-13 19:25:00,414 | /home/anil/medley/apps/frappe/frappe/utils/scheduler.py:
Site: ordermedicine
Access denied for site ordermedicine
[DEBUG] 2020-11-13 19:25:00,552 | /home/anil/medley/apps/frappe/frappe/utils/scheduler.py:
Site: ordermedicines
Queued events for site ordermedicines
[DEBUG] 2020-11-13 19:26:00,626 | /home/anil/medley/apps/frappe/frappe/utils/scheduler.py:
Site: ordermedicine
Access denied for site ordermedicine
[DEBUG] 2020-11-13 19:26:00,778 | /home/anil/medley/apps/frappe/frappe/utils/scheduler.py:
Site: ordermedicines
Queued events for site ordermedicines
[ERROR] 2020-11-13 19:26:20,921 | /home/anil/medley/apps/frappe/frappe/app.py:
Site: ordermedicines
Form Dict: {
 "cmd": "erpnext.selling.page.point_of_sale.point_of_sale.get_items",
 "item_group": "All Item Groups",
 "page_length": "40",
 "search_value": "",
 "start": "0"
}
Request Error
Traceback (most recent call last):
  File "/home/anil/medley/apps/frappe/frappe/app.py", line 64, in application
    response = frappe.api.handle()
  File "/home/anil/medley/apps/frappe/frappe/api.py", line 59, in handle
    return frappe.handler.handle()
  File "/home/anil/medley/apps/frappe/frappe/handler.py", line 24, in handle
    data = execute_cmd(cmd)
  File "/home/anil/medley/apps/frappe/frappe/handler.py", line 64, in execute_cmd
    return frappe.call(method, **frappe.form_dict)
  File "/home/anil/medley/apps/frappe/frappe/__init__.py", line 1064, in call
    return fn(*args, **newargs)
TypeError: get_items() missing 1 required positional argument: 'price_list'
[ERROR] 2020-11-13 19:26:20,928 | /home/anil/medley/apps/frappe/frappe/utils/error.py:
New Exception collected with id: 2020-11-13 19:26:20.922835-127.0.0.1-ef1
[ERROR] 2020-11-13 19:26:21,762 | /home/anil/medley/apps/frappe/frappe/app.py:
Site: ordermedicines
Form Dict: {
 "cmd": "erpnext.regional.india.utils.get_regional_address_details",
 "company": "Medley",
 "doctype": "Sales Invoice",
 "party_details": "{\"shipping_address\":\"\",\"shipping_address_name\":\"\",\"customer_address\":\"\",\"customer\":\"\"}",
 "return_taxes": "1"
}
Request Error
Traceback (most recent call last):
  File "/home/anil/medley/apps/frappe/frappe/app.py", line 64, in application
    response = frappe.api.handle()
  File "/home/anil/medley/apps/frappe/frappe/api.py", line 59, in handle
    return frappe.handler.handle()
  File "/home/anil/medley/apps/frappe/frappe/handler.py", line 24, in handle
    data = execute_cmd(cmd)
  File "/home/anil/medley/apps/frappe/frappe/handler.py", line 64, in execute_cmd
    return frappe.call(method, **frappe.form_dict)
  File "/home/anil/medley/apps/frappe/frappe/__init__.py", line 1064, in call
    return fn(*args, **newargs)
  File "/home/anil/medley/apps/erpnext/erpnext/regional/india/utils.py", line 162, in get_regional_address_details
    get_tax_template_for_sez(party_details, master_doctype, company, 'Customer')
  File "/home/anil/medley/apps/erpnext/erpnext/regional/india/utils.py", line 229, in get_tax_template_for_sez
    gst_details = frappe.db.get_value(party_type, {'name': party_details.get(frappe.scrub(party_type))},
  File "/home/anil/medley/apps/frappe/frappe/database/database.py", line 400, in get_value
    ret = self.get_values(doctype, filters, fieldname, ignore, as_dict, debug,
  File "/home/anil/medley/apps/frappe/frappe/database/database.py", line 445, in get_values
    out = self._get_values_from_table(fields, filters, doctype, as_dict, debug, order_by, update)
  File "/home/anil/medley/apps/frappe/frappe/database/database.py", line 590, in _get_values_from_table
    r = self.sql("select {0} from `tab{1}` {2} {3} {4}"
  File "/home/anil/medley/apps/frappe/frappe/database/database.py", line 156, in sql
    self._cursor.execute(query, values)
  File "/home/anil/medley/env/lib/python3.8/site-packages/pymysql/cursors.py", line 170, in execute
    result = self._query(query)
  File "/home/anil/medley/env/lib/python3.8/site-packages/pymysql/cursors.py", line 328, in _query
    conn.query(q)
  File "/home/anil/medley/env/lib/python3.8/site-packages/pymysql/connections.py", line 517, in query
    self._affected_rows = self._read_query_result(unbuffered=unbuffered)
  File "/home/anil/medley/env/lib/python3.8/site-packages/pymysql/connections.py", line 732, in _read_query_result
    result.read()
  File "/home/anil/medley/env/lib/python3.8/site-packages/pymysql/connections.py", line 1075, in read
    first_packet = self.connection._read_packet()
  File "/home/anil/medley/env/lib/python3.8/site-packages/pymysql/connections.py", line 684, in _read_packet
    packet.check_error()
  File "/home/anil/medley/env/lib/python3.8/site-packages/pymysql/protocol.py", line 220, in check_error
    err.raise_mysql_exception(self._data)
  File "/home/anil/medley/env/lib/python3.8/site-packages/pymysql/err.py", line 109, in raise_mysql_exception
    raise errorclass(errno, errval)
pymysql.err.InternalError: (1054, "Unknown column 'gst_category' in 'field list'")
[ERROR] 2020-11-13 19:26:21,775 | /home/anil/medley/apps/frappe/frappe/utils/error.py:
New Exception collected with id: 2020-11-13 19:26:21.763210-127.0.0.1-d33
[DEBUG] 2020-11-13 19:27:00,851 | /home/anil/medley/apps/frappe/frappe/utils/scheduler.py:
Site: ordermedicine
Access denied for site ordermedicine
[DEBUG] 2020-11-13 19:27:01,025 | /home/anil/medley/apps/frappe/frappe/utils/scheduler.py:
Site: ordermedicines
Queued events for site ordermedicines
[ERROR] 2020-11-13 19:27:05,559 | /home/anil/medley/apps/frappe/frappe/app.py:
Site: ordermedicines
Form Dict: {
 "cmd": "erpnext.selling.page.point_of_sale.point_of_sale.get_items",
 "item_group": "All Item Groups",
 "page_length": "40",
 "search_value": "",
 "start": "0"
}
Request Error
Traceback (most recent call last):
  File "/home/anil/medley/apps/frappe/frappe/app.py", line 64, in application
    response = frappe.api.handle()
  File "/home/anil/medley/apps/frappe/frappe/api.py", line 59, in handle
    return frappe.handler.handle()
  File "/home/anil/medley/apps/frappe/frappe/handler.py", line 24, in handle
    data = execute_cmd(cmd)
  File "/home/anil/medley/apps/frappe/frappe/handler.py", line 64, in execute_cmd
    return frappe.call(method, **frappe.form_dict)
  File "/home/anil/medley/apps/frappe/frappe/__init__.py", line 1064, in call
    return fn(*args, **newargs)
TypeError: get_items() missing 1 required positional argument: 'price_list'
[ERROR] 2020-11-13 19:27:05,569 | /home/anil/medley/apps/frappe/frappe/utils/error.py:
New Exception collected with id: 2020-11-13 19:27:05.560037-127.0.0.1-c0d
[ERROR] 2020-11-13 19:27:06,491 | /home/anil/medley/apps/frappe/frappe/app.py:
Site: ordermedicines
Form Dict: {
 "cmd": "erpnext.regional.india.utils.get_regional_address_details",
 "company": "Medley",
 "doctype": "Sales Invoice",
 "party_details": "{\"shipping_address\":\"\",\"shipping_address_name\":\"\",\"customer_address\":\"\",\"customer\":\"\"}",
 "return_taxes": "1"
}
Request Error
Traceback (most recent call last):
  File "/home/anil/medley/apps/frappe/frappe/app.py", line 64, in application
    response = frappe.api.handle()
  File "/home/anil/medley/apps/frappe/frappe/api.py", line 59, in handle
    return frappe.handler.handle()
  File "/home/anil/medley/apps/frappe/frappe/handler.py", line 24, in handle
    data = execute_cmd(cmd)
  File "/home/anil/medley/apps/frappe/frappe/handler.py", line 64, in execute_cmd
    return frappe.call(method, **frappe.form_dict)
  File "/home/anil/medley/apps/frappe/frappe/__init__.py", line 1064, in call
    return fn(*args, **newargs)
  File "/home/anil/medley/apps/erpnext/erpnext/regional/india/utils.py", line 162, in get_regional_address_details
    get_tax_template_for_sez(party_details, master_doctype, company, 'Customer')
  File "/home/anil/medley/apps/erpnext/erpnext/regional/india/utils.py", line 229, in get_tax_template_for_sez
    gst_details = frappe.db.get_value(party_type, {'name': party_details.get(frappe.scrub(party_type))},
  File "/home/anil/medley/apps/frappe/frappe/database/database.py", line 400, in get_value
    ret = self.get_values(doctype, filters, fieldname, ignore, as_dict, debug,
  File "/home/anil/medley/apps/frappe/frappe/database/database.py", line 445, in get_values
    out = self._get_values_from_table(fields, filters, doctype, as_dict, debug, order_by, update)
  File "/home/anil/medley/apps/frappe/frappe/database/database.py", line 590, in _get_values_from_table
    r = self.sql("select {0} from `tab{1}` {2} {3} {4}"
  File "/home/anil/medley/apps/frappe/frappe/database/database.py", line 156, in sql
    self._cursor.execute(query, values)
  File "/home/anil/medley/env/lib/python3.8/site-packages/pymysql/cursors.py", line 170, in execute
    result = self._query(query)
  File "/home/anil/medley/env/lib/python3.8/site-packages/pymysql/cursors.py", line 328, in _query
    conn.query(q)
  File "/home/anil/medley/env/lib/python3.8/site-packages/pymysql/connections.py", line 517, in query
    self._affected_rows = self._read_query_result(unbuffered=unbuffered)
  File "/home/anil/medley/env/lib/python3.8/site-packages/pymysql/connections.py", line 732, in _read_query_result
    result.read()
  File "/home/anil/medley/env/lib/python3.8/site-packages/pymysql/connections.py", line 1075, in read
    first_packet = self.connection._read_packet()
  File "/home/anil/medley/env/lib/python3.8/site-packages/pymysql/connections.py", line 684, in _read_packet
    packet.check_error()
  File "/home/anil/medley/env/lib/python3.8/site-packages/pymysql/protocol.py", line 220, in check_error
    err.raise_mysql_exception(self._data)
  File "/home/anil/medley/env/lib/python3.8/site-packages/pymysql/err.py", line 109, in raise_mysql_exception
    raise errorclass(errno, errval)
pymysql.err.InternalError: (1054, "Unknown column 'gst_category' in 'field list'")
[ERROR] 2020-11-13 19:27:06,503 | /home/anil/medley/apps/frappe/frappe/utils/error.py:
New Exception collected with id: 2020-11-13 19:27:06.492346-127.0.0.1-e94
[ERROR] 2020-11-13 19:27:40,043 | /home/anil/medley/apps/frappe/frappe/app.py:
Site: ordermedicines
Form Dict: {
 "cmd": "erpnext.selling.page.point_of_sale.point_of_sale.get_items",
 "item_group": "All Item Groups",
 "page_length": "40",
 "search_value": "",
 "start": "0"
}
Request Error
Traceback (most recent call last):
  File "/home/anil/medley/apps/frappe/frappe/app.py", line 64, in application
    response = frappe.api.handle()
  File "/home/anil/medley/apps/frappe/frappe/api.py", line 59, in handle
    return frappe.handler.handle()
  File "/home/anil/medley/apps/frappe/frappe/handler.py", line 24, in handle
    data = execute_cmd(cmd)
  File "/home/anil/medley/apps/frappe/frappe/handler.py", line 64, in execute_cmd
    return frappe.call(method, **frappe.form_dict)
  File "/home/anil/medley/apps/frappe/frappe/__init__.py", line 1064, in call
    return fn(*args, **newargs)
TypeError: get_items() missing 1 required positional argument: 'price_list'
[ERROR] 2020-11-13 19:27:40,049 | /home/anil/medley/apps/frappe/frappe/utils/error.py:
New Exception collected with id: 2020-11-13 19:27:40.044329-127.0.0.1-6a3
[ERROR] 2020-11-13 19:27:40,768 | /home/anil/medley/apps/frappe/frappe/app.py:
Site: ordermedicines
Form Dict: {
 "cmd": "erpnext.regional.india.utils.get_regional_address_details",
 "company": "Medley",
 "doctype": "Sales Invoice",
 "party_details": "{\"shipping_address\":\"\",\"shipping_address_name\":\"\",\"customer_address\":\"\",\"customer\":\"\"}",
 "return_taxes": "1"
}
Request Error
Traceback (most recent call last):
  File "/home/anil/medley/apps/frappe/frappe/app.py", line 64, in application
    response = frappe.api.handle()
  File "/home/anil/medley/apps/frappe/frappe/api.py", line 59, in handle
    return frappe.handler.handle()
  File "/home/anil/medley/apps/frappe/frappe/handler.py", line 24, in handle
    data = execute_cmd(cmd)
  File "/home/anil/medley/apps/frappe/frappe/handler.py", line 64, in execute_cmd
    return frappe.call(method, **frappe.form_dict)
  File "/home/anil/medley/apps/frappe/frappe/__init__.py", line 1064, in call
    return fn(*args, **newargs)
  File "/home/anil/medley/apps/erpnext/erpnext/regional/india/utils.py", line 162, in get_regional_address_details
    get_tax_template_for_sez(party_details, master_doctype, company, 'Customer')
  File "/home/anil/medley/apps/erpnext/erpnext/regional/india/utils.py", line 229, in get_tax_template_for_sez
    gst_details = frappe.db.get_value(party_type, {'name': party_details.get(frappe.scrub(party_type))},
  File "/home/anil/medley/apps/frappe/frappe/database/database.py", line 400, in get_value
    ret = self.get_values(doctype, filters, fieldname, ignore, as_dict, debug,
  File "/home/anil/medley/apps/frappe/frappe/database/database.py", line 445, in get_values
    out = self._get_values_from_table(fields, filters, doctype, as_dict, debug, order_by, update)
  File "/home/anil/medley/apps/frappe/frappe/database/database.py", line 590, in _get_values_from_table
    r = self.sql("select {0} from `tab{1}` {2} {3} {4}"
  File "/home/anil/medley/apps/frappe/frappe/database/database.py", line 156, in sql
    self._cursor.execute(query, values)
  File "/home/anil/medley/env/lib/python3.8/site-packages/pymysql/cursors.py", line 170, in execute
    result = self._query(query)
  File "/home/anil/medley/env/lib/python3.8/site-packages/pymysql/cursors.py", line 328, in _query
    conn.query(q)
  File "/home/anil/medley/env/lib/python3.8/site-packages/pymysql/connections.py", line 517, in query
    self._affected_rows = self._read_query_result(unbuffered=unbuffered)
  File "/home/anil/medley/env/lib/python3.8/site-packages/pymysql/connections.py", line 732, in _read_query_result
    result.read()
  File "/home/anil/medley/env/lib/python3.8/site-packages/pymysql/connections.py", line 1075, in read
    first_packet = self.connection._read_packet()
  File "/home/anil/medley/env/lib/python3.8/site-packages/pymysql/connections.py", line 684, in _read_packet
    packet.check_error()
  File "/home/anil/medley/env/lib/python3.8/site-packages/pymysql/protocol.py", line 220, in check_error
    err.raise_mysql_exception(self._data)
  File "/home/anil/medley/env/lib/python3.8/site-packages/pymysql/err.py", line 109, in raise_mysql_exception
    raise errorclass(errno, errval)
pymysql.err.InternalError: (1054, "Unknown column 'gst_category' in 'field list'")
[ERROR] 2020-11-13 19:27:40,774 | /home/anil/medley/apps/frappe/frappe/utils/error.py:
New Exception collected with id: 2020-11-13 19:27:40.769093-127.0.0.1-b6e
[DEBUG] 2020-11-13 19:28:01,108 | /home/anil/medley/apps/frappe/frappe/utils/scheduler.py:
Site: ordermedicine
Access denied for site ordermedicine
[DEBUG] 2020-11-13 19:28:01,316 | /home/anil/medley/apps/frappe/frappe/utils/scheduler.py:
Site: ordermedicines
Queued events for site ordermedicines
[ERROR] 2020-11-13 19:28:20,394 | /home/anil/medley/apps/frappe/frappe/app.py:
Site: ordermedicines
Form Dict: {
 "cmd": "erpnext.selling.page.point_of_sale.point_of_sale.get_items",
 "item_group": "All Item Groups",
 "page_length": "40",
 "search_value": "",
 "start": "0"
}
Request Error
Traceback (most recent call last):
  File "/home/anil/medley/apps/frappe/frappe/app.py", line 64, in application
    response = frappe.api.handle()
  File "/home/anil/medley/apps/frappe/frappe/api.py", line 59, in handle
    return frappe.handler.handle()
  File "/home/anil/medley/apps/frappe/frappe/handler.py", line 24, in handle
    data = execute_cmd(cmd)
  File "/home/anil/medley/apps/frappe/frappe/handler.py", line 64, in execute_cmd
    return frappe.call(method, **frappe.form_dict)
  File "/home/anil/medley/apps/frappe/frappe/__init__.py", line 1064, in call
    return fn(*args, **newargs)
TypeError: get_items() missing 1 required positional argument: 'price_list'
[ERROR] 2020-11-13 19:28:20,399 | /home/anil/medley/apps/frappe/frappe/utils/error.py:
New Exception collected with id: 2020-11-13 19:28:20.395172-127.0.0.1-b6f
[ERROR] 2020-11-13 19:28:21,071 | /home/anil/medley/apps/frappe/frappe/app.py:
Site: ordermedicines
Form Dict: {
 "cmd": "erpnext.regional.india.utils.get_regional_address_details",
 "company": "Medley",
 "doctype": "Sales Invoice",
 "party_details": "{\"shipping_address\":\"\",\"shipping_address_name\":\"\",\"customer_address\":\"\",\"customer\":\"\"}",
 "return_taxes": "1"
}
Request Error
Traceback (most recent call last):
  File "/home/anil/medley/apps/frappe/frappe/app.py", line 64, in application
    response = frappe.api.handle()
  File "/home/anil/medley/apps/frappe/frappe/api.py", line 59, in handle
    return frappe.handler.handle()
  File "/home/anil/medley/apps/frappe/frappe/handler.py", line 24, in handle
    data = execute_cmd(cmd)
  File "/home/anil/medley/apps/frappe/frappe/handler.py", line 64, in execute_cmd
    return frappe.call(method, **frappe.form_dict)
  File "/home/anil/medley/apps/frappe/frappe/__init__.py", line 1064, in call
    return fn(*args, **newargs)
  File "/home/anil/medley/apps/erpnext/erpnext/regional/india/utils.py", line 162, in get_regional_address_details
    get_tax_template_for_sez(party_details, master_doctype, company, 'Customer')
  File "/home/anil/medley/apps/erpnext/erpnext/regional/india/utils.py", line 229, in get_tax_template_for_sez
    gst_details = frappe.db.get_value(party_type, {'name': party_details.get(frappe.scrub(party_type))},
  File "/home/anil/medley/apps/frappe/frappe/database/database.py", line 400, in get_value
    ret = self.get_values(doctype, filters, fieldname, ignore, as_dict, debug,
  File "/home/anil/medley/apps/frappe/frappe/database/database.py", line 445, in get_values
    out = self._get_values_from_table(fields, filters, doctype, as_dict, debug, order_by, update)
  File "/home/anil/medley/apps/frappe/frappe/database/database.py", line 590, in _get_values_from_table
    r = self.sql("select {0} from `tab{1}` {2} {3} {4}"
  File "/home/anil/medley/apps/frappe/frappe/database/database.py", line 156, in sql
    self._cursor.execute(query, values)
  File "/home/anil/medley/env/lib/python3.8/site-packages/pymysql/cursors.py", line 170, in execute
    result = self._query(query)
  File "/home/anil/medley/env/lib/python3.8/site-packages/pymysql/cursors.py", line 328, in _query
    conn.query(q)
  File "/home/anil/medley/env/lib/python3.8/site-packages/pymysql/connections.py", line 517, in query
    self._affected_rows = self._read_query_result(unbuffered=unbuffered)
  File "/home/anil/medley/env/lib/python3.8/site-packages/pymysql/connections.py", line 732, in _read_query_result
    result.read()
  File "/home/anil/medley/env/lib/python3.8/site-packages/pymysql/connections.py", line 1075, in read
    first_packet = self.connection._read_packet()
  File "/home/anil/medley/env/lib/python3.8/site-packages/pymysql/connections.py", line 684, in _read_packet
    packet.check_error()
  File "/home/anil/medley/env/lib/python3.8/site-packages/pymysql/protocol.py", line 220, in check_error
    err.raise_mysql_exception(self._data)
  File "/home/anil/medley/env/lib/python3.8/site-packages/pymysql/err.py", line 109, in raise_mysql_exception
    raise errorclass(errno, errval)
pymysql.err.InternalError: (1054, "Unknown column 'gst_category' in 'field list'")
[ERROR] 2020-11-13 19:28:21,078 | /home/anil/medley/apps/frappe/frappe/utils/error.py:
New Exception collected with id: 2020-11-13 19:28:21.071797-127.0.0.1-d60
[DEBUG] 2020-11-13 19:29:01,395 | /home/anil/medley/apps/frappe/frappe/utils/scheduler.py:
Site: ordermedicine
Access denied for site ordermedicine
[DEBUG] 2020-11-13 19:29:01,527 | /home/anil/medley/apps/frappe/frappe/utils/scheduler.py:
Site: ordermedicines
Queued events for site ordermedicines
[DEBUG] 2020-11-13 19:30:01,595 | /home/anil/medley/apps/frappe/frappe/utils/scheduler.py:
Site: ordermedicine
Access denied for site ordermedicine
[DEBUG] 2020-11-13 19:30:01,731 | /home/anil/medley/apps/frappe/frappe/utils/scheduler.py:
Site: ordermedicines
Queued events for site ordermedicines
[DEBUG] 2020-11-13 19:31:01,810 | /home/anil/medley/apps/frappe/frappe/utils/scheduler.py:
Site: ordermedicine
Access denied for site ordermedicine
[DEBUG] 2020-11-13 19:31:02,057 | /home/anil/medley/apps/frappe/frappe/utils/scheduler.py:
Site: ordermedicines
Queued events for site ordermedicines
[DEBUG] 2020-11-13 19:32:02,129 | /home/anil/medley/apps/frappe/frappe/utils/scheduler.py:
Site: ordermedicine
Access denied for site ordermedicine
[DEBUG] 2020-11-13 19:32:02,293 | /home/anil/medley/apps/frappe/frappe/utils/scheduler.py:
Site: ordermedicines
Queued events for site ordermedicines
[DEBUG] 2020-11-13 19:33:02,371 | /home/anil/medley/apps/frappe/frappe/utils/scheduler.py:
Site: ordermedicine
Access denied for site ordermedicine
[DEBUG] 2020-11-13 19:33:02,513 | /home/anil/medley/apps/frappe/frappe/utils/scheduler.py:
Site: ordermedicines
Queued events for site ordermedicines
[DEBUG] 2020-11-13 19:34:02,595 | /home/anil/medley/apps/frappe/frappe/utils/scheduler.py:
Site: ordermedicine
Access denied for site ordermedicine
[DEBUG] 2020-11-13 19:34:02,801 | /home/anil/medley/apps/frappe/frappe/utils/scheduler.py:
Site: ordermedicines
Queued events for site ordermedicines
[DEBUG] 2020-11-13 19:35:02,890 | /home/anil/medley/apps/frappe/frappe/utils/scheduler.py:
Site: ordermedicine
Access denied for site ordermedicine
[DEBUG] 2020-11-13 19:35:03,005 | /home/anil/medley/apps/frappe/frappe/utils/scheduler.py:
Site: ordermedicines
Queued events for site ordermedicines
[ERROR] 2020-11-13 19:35:41,025 | /home/anil/medley/apps/frappe/frappe/app.py:
Site: ordermedicines
Form Dict: {
 "cmd": "erpnext.selling.page.point_of_sale.point_of_sale.get_items",
 "item_group": "All Item Groups",
 "page_length": "40",
 "search_value": "",
 "start": "0"
}
Request Error
Traceback (most recent call last):
  File "/home/anil/medley/apps/frappe/frappe/app.py", line 64, in application
    response = frappe.api.handle()
  File "/home/anil/medley/apps/frappe/frappe/api.py", line 59, in handle
    return frappe.handler.handle()
  File "/home/anil/medley/apps/frappe/frappe/handler.py", line 24, in handle
    data = execute_cmd(cmd)
  File "/home/anil/medley/apps/frappe/frappe/handler.py", line 64, in execute_cmd
    return frappe.call(method, **frappe.form_dict)
  File "/home/anil/medley/apps/frappe/frappe/__init__.py", line 1064, in call
    return fn(*args, **newargs)
TypeError: get_items() missing 1 required positional argument: 'price_list'
[ERROR] 2020-11-13 19:35:41,057 | /home/anil/medley/apps/frappe/frappe/utils/error.py:
New Exception collected with id: 2020-11-13 19:35:41.025979-127.0.0.1-33c
[ERROR] 2020-11-13 19:35:41,563 | /home/anil/medley/apps/frappe/frappe/app.py:
Site: ordermedicines
Form Dict: {
 "cmd": "erpnext.regional.india.utils.get_regional_address_details",
 "company": "Medley",
 "doctype": "Sales Invoice",
 "party_details": "{\"shipping_address\":\"\",\"shipping_address_name\":\"\",\"customer_address\":\"\",\"customer\":\"\"}",
 "return_taxes": "1"
}
Request Error
Traceback (most recent call last):
  File "/home/anil/medley/apps/frappe/frappe/app.py", line 64, in application
    response = frappe.api.handle()
  File "/home/anil/medley/apps/frappe/frappe/api.py", line 59, in handle
    return frappe.handler.handle()
  File "/home/anil/medley/apps/frappe/frappe/handler.py", line 24, in handle
    data = execute_cmd(cmd)
  File "/home/anil/medley/apps/frappe/frappe/handler.py", line 64, in execute_cmd
    return frappe.call(method, **frappe.form_dict)
  File "/home/anil/medley/apps/frappe/frappe/__init__.py", line 1064, in call
    return fn(*args, **newargs)
  File "/home/anil/medley/apps/erpnext/erpnext/regional/india/utils.py", line 162, in get_regional_address_details
    get_tax_template_for_sez(party_details, master_doctype, company, 'Customer')
  File "/home/anil/medley/apps/erpnext/erpnext/regional/india/utils.py", line 229, in get_tax_template_for_sez
    gst_details = frappe.db.get_value(party_type, {'name': party_details.get(frappe.scrub(party_type))},
  File "/home/anil/medley/apps/frappe/frappe/database/database.py", line 400, in get_value
    ret = self.get_values(doctype, filters, fieldname, ignore, as_dict, debug,
  File "/home/anil/medley/apps/frappe/frappe/database/database.py", line 445, in get_values
    out = self._get_values_from_table(fields, filters, doctype, as_dict, debug, order_by, update)
  File "/home/anil/medley/apps/frappe/frappe/database/database.py", line 590, in _get_values_from_table
    r = self.sql("select {0} from `tab{1}` {2} {3} {4}"
  File "/home/anil/medley/apps/frappe/frappe/database/database.py", line 156, in sql
    self._cursor.execute(query, values)
  File "/home/anil/medley/env/lib/python3.8/site-packages/pymysql/cursors.py", line 170, in execute
    result = self._query(query)
  File "/home/anil/medley/env/lib/python3.8/site-packages/pymysql/cursors.py", line 328, in _query
    conn.query(q)
  File "/home/anil/medley/env/lib/python3.8/site-packages/pymysql/connections.py", line 517, in query
    self._affected_rows = self._read_query_result(unbuffered=unbuffered)
  File "/home/anil/medley/env/lib/python3.8/site-packages/pymysql/connections.py", line 732, in _read_query_result
    result.read()
  File "/home/anil/medley/env/lib/python3.8/site-packages/pymysql/connections.py", line 1075, in read
    first_packet = self.connection._read_packet()
  File "/home/anil/medley/env/lib/python3.8/site-packages/pymysql/connections.py", line 684, in _read_packet
    packet.check_error()
  File "/home/anil/medley/env/lib/python3.8/site-packages/pymysql/protocol.py", line 220, in check_error
    err.raise_mysql_exception(self._data)
  File "/home/anil/medley/env/lib/python3.8/site-packages/pymysql/err.py", line 109, in raise_mysql_exception
    raise errorclass(errno, errval)
pymysql.err.InternalError: (1054, "Unknown column 'gst_category' in 'field list'")
[ERROR] 2020-11-13 19:35:41,575 | /home/anil/medley/apps/frappe/frappe/utils/error.py:
New Exception collected with id: 2020-11-13 19:35:41.564430-127.0.0.1-089
[DEBUG] 2020-11-13 19:36:03,076 | /home/anil/medley/apps/frappe/frappe/utils/scheduler.py:
Site: ordermedicine
Access denied for site ordermedicine
[DEBUG] 2020-11-13 19:36:03,260 | /home/anil/medley/apps/frappe/frappe/utils/scheduler.py:
Site: ordermedicines
Queued events for site ordermedicines
[DEBUG] 2020-11-13 19:37:03,324 | /home/anil/medley/apps/frappe/frappe/utils/scheduler.py:
Site: ordermedicine
Access denied for site ordermedicine
[DEBUG] 2020-11-13 19:37:03,486 | /home/anil/medley/apps/frappe/frappe/utils/scheduler.py:
Site: ordermedicines
Queued events for site ordermedicines
[DEBUG] 2020-11-13 19:38:03,563 | /home/anil/medley/apps/frappe/frappe/utils/scheduler.py:
Site: ordermedicine
Access denied for site ordermedicine
[DEBUG] 2020-11-13 19:38:03,708 | /home/anil/medley/apps/frappe/frappe/utils/scheduler.py:
Site: ordermedicines
Queued events for site ordermedicines
[ERROR] 2020-11-13 19:38:25,073 | /home/anil/medley/apps/frappe/frappe/app.py:
Site: ordermedicines
Form Dict: {
 "cmd": "erpnext.regional.india.utils.get_regional_address_details",
 "company": "Medley",
 "doctype": "Sales Invoice",
 "party_details": "{\"shipping_address\":\"\",\"shipping_address_name\":\"\",\"customer_address\":\"\",\"customer\":\"\"}",
 "return_taxes": "1"
}
Request Error
Traceback (most recent call last):
  File "/home/anil/medley/apps/frappe/frappe/app.py", line 64, in application
    response = frappe.api.handle()
  File "/home/anil/medley/apps/frappe/frappe/api.py", line 59, in handle
    return frappe.handler.handle()
  File "/home/anil/medley/apps/frappe/frappe/handler.py", line 24, in handle
    data = execute_cmd(cmd)
  File "/home/anil/medley/apps/frappe/frappe/handler.py", line 64, in execute_cmd
    return frappe.call(method, **frappe.form_dict)
  File "/home/anil/medley/apps/frappe/frappe/__init__.py", line 1064, in call
    return fn(*args, **newargs)
  File "/home/anil/medley/apps/erpnext/erpnext/regional/india/utils.py", line 162, in get_regional_address_details
    get_tax_template_for_sez(party_details, master_doctype, company, 'Customer')
  File "/home/anil/medley/apps/erpnext/erpnext/regional/india/utils.py", line 229, in get_tax_template_for_sez
    gst_details = frappe.db.get_value(party_type, {'name': party_details.get(frappe.scrub(party_type))},
  File "/home/anil/medley/apps/frappe/frappe/database/database.py", line 400, in get_value
    ret = self.get_values(doctype, filters, fieldname, ignore, as_dict, debug,
  File "/home/anil/medley/apps/frappe/frappe/database/database.py", line 445, in get_values
    out = self._get_values_from_table(fields, filters, doctype, as_dict, debug, order_by, update)
  File "/home/anil/medley/apps/frappe/frappe/database/database.py", line 590, in _get_values_from_table
    r = self.sql("select {0} from `tab{1}` {2} {3} {4}"
  File "/home/anil/medley/apps/frappe/frappe/database/database.py", line 156, in sql
    self._cursor.execute(query, values)
  File "/home/anil/medley/env/lib/python3.8/site-packages/pymysql/cursors.py", line 170, in execute
    result = self._query(query)
  File "/home/anil/medley/env/lib/python3.8/site-packages/pymysql/cursors.py", line 328, in _query
    conn.query(q)
  File "/home/anil/medley/env/lib/python3.8/site-packages/pymysql/connections.py", line 517, in query
    self._affected_rows = self._read_query_result(unbuffered=unbuffered)
  File "/home/anil/medley/env/lib/python3.8/site-packages/pymysql/connections.py", line 732, in _read_query_result
    result.read()
  File "/home/anil/medley/env/lib/python3.8/site-packages/pymysql/connections.py", line 1075, in read
    first_packet = self.connection._read_packet()
  File "/home/anil/medley/env/lib/python3.8/site-packages/pymysql/connections.py", line 684, in _read_packet
    packet.check_error()
  File "/home/anil/medley/env/lib/python3.8/site-packages/pymysql/protocol.py", line 220, in check_error
    err.raise_mysql_exception(self._data)
  File "/home/anil/medley/env/lib/python3.8/site-packages/pymysql/err.py", line 109, in raise_mysql_exception
    raise errorclass(errno, errval)
pymysql.err.InternalError: (1054, "Unknown column 'gst_category' in 'field list'")
[ERROR] 2020-11-13 19:38:25,090 | /home/anil/medley/apps/frappe/frappe/utils/error.py:
New Exception collected with id: 2020-11-13 19:38:25.074941-127.0.0.1-66b
[ERROR] 2020-11-13 19:38:26,519 | /home/anil/medley/apps/frappe/frappe/app.py:
Site: ordermedicines
Form Dict: {
 "cmd": "erpnext.regional.india.utils.get_regional_address_details",
 "company": "Medley",
 "doctype": "Sales Invoice",
 "party_details": "{\"shipping_address\":\"\",\"shipping_address_name\":\"\",\"customer_address\":\"\",\"customer\":\"\"}",
 "return_taxes": "1"
}
Request Error
Traceback (most recent call last):
  File "/home/anil/medley/apps/frappe/frappe/app.py", line 64, in application
    response = frappe.api.handle()
  File "/home/anil/medley/apps/frappe/frappe/api.py", line 59, in handle
    return frappe.handler.handle()
  File "/home/anil/medley/apps/frappe/frappe/handler.py", line 24, in handle
    data = execute_cmd(cmd)
  File "/home/anil/medley/apps/frappe/frappe/handler.py", line 64, in execute_cmd
    return frappe.call(method, **frappe.form_dict)
  File "/home/anil/medley/apps/frappe/frappe/__init__.py", line 1064, in call
    return fn(*args, **newargs)
  File "/home/anil/medley/apps/erpnext/erpnext/regional/india/utils.py", line 162, in get_regional_address_details
    get_tax_template_for_sez(party_details, master_doctype, company, 'Customer')
  File "/home/anil/medley/apps/erpnext/erpnext/regional/india/utils.py", line 229, in get_tax_template_for_sez
    gst_details = frappe.db.get_value(party_type, {'name': party_details.get(frappe.scrub(party_type))},
  File "/home/anil/medley/apps/frappe/frappe/database/database.py", line 400, in get_value
    ret = self.get_values(doctype, filters, fieldname, ignore, as_dict, debug,
  File "/home/anil/medley/apps/frappe/frappe/database/database.py", line 445, in get_values
    out = self._get_values_from_table(fields, filters, doctype, as_dict, debug, order_by, update)
  File "/home/anil/medley/apps/frappe/frappe/database/database.py", line 590, in _get_values_from_table
    r = self.sql("select {0} from `tab{1}` {2} {3} {4}"
  File "/home/anil/medley/apps/frappe/frappe/database/database.py", line 156, in sql
    self._cursor.execute(query, values)
  File "/home/anil/medley/env/lib/python3.8/site-packages/pymysql/cursors.py", line 170, in execute
    result = self._query(query)
  File "/home/anil/medley/env/lib/python3.8/site-packages/pymysql/cursors.py", line 328, in _query
    conn.query(q)
  File "/home/anil/medley/env/lib/python3.8/site-packages/pymysql/connections.py", line 517, in query
    self._affected_rows = self._read_query_result(unbuffered=unbuffered)
  File "/home/anil/medley/env/lib/python3.8/site-packages/pymysql/connections.py", line 732, in _read_query_result
    result.read()
  File "/home/anil/medley/env/lib/python3.8/site-packages/pymysql/connections.py", line 1075, in read
    first_packet = self.connection._read_packet()
  File "/home/anil/medley/env/lib/python3.8/site-packages/pymysql/connections.py", line 684, in _read_packet
    packet.check_error()
  File "/home/anil/medley/env/lib/python3.8/site-packages/pymysql/protocol.py", line 220, in check_error
    err.raise_mysql_exception(self._data)
  File "/home/anil/medley/env/lib/python3.8/site-packages/pymysql/err.py", line 109, in raise_mysql_exception
    raise errorclass(errno, errval)
pymysql.err.InternalError: (1054, "Unknown column 'gst_category' in 'field list'")
[ERROR] 2020-11-13 19:38:26,536 | /home/anil/medley/apps/frappe/frappe/utils/error.py:
New Exception collected with id: 2020-11-13 19:38:26.520458-127.0.0.1-ccb
[ERROR] 2020-11-13 19:38:38,979 | /home/anil/medley/apps/frappe/frappe/app.py:
Site: ordermedicines
Form Dict: {
 "cmd": "erpnext.regional.india.utils.get_regional_address_details",
 "company": "Medley",
 "doctype": "Sales Invoice",
 "party_details": "{\"shipping_address\":\"\",\"shipping_address_name\":\"\",\"customer_address\":\"\",\"customer\":\"\"}",
 "return_taxes": "1"
}
Request Error
Traceback (most recent call last):
  File "/home/anil/medley/apps/frappe/frappe/app.py", line 64, in application
    response = frappe.api.handle()
  File "/home/anil/medley/apps/frappe/frappe/api.py", line 59, in handle
    return frappe.handler.handle()
  File "/home/anil/medley/apps/frappe/frappe/handler.py", line 24, in handle
    data = execute_cmd(cmd)
  File "/home/anil/medley/apps/frappe/frappe/handler.py", line 64, in execute_cmd
    return frappe.call(method, **frappe.form_dict)
  File "/home/anil/medley/apps/frappe/frappe/__init__.py", line 1064, in call
    return fn(*args, **newargs)
  File "/home/anil/medley/apps/erpnext/erpnext/regional/india/utils.py", line 162, in get_regional_address_details
    get_tax_template_for_sez(party_details, master_doctype, company, 'Customer')
  File "/home/anil/medley/apps/erpnext/erpnext/regional/india/utils.py", line 229, in get_tax_template_for_sez
    gst_details = frappe.db.get_value(party_type, {'name': party_details.get(frappe.scrub(party_type))},
  File "/home/anil/medley/apps/frappe/frappe/database/database.py", line 400, in get_value
    ret = self.get_values(doctype, filters, fieldname, ignore, as_dict, debug,
  File "/home/anil/medley/apps/frappe/frappe/database/database.py", line 445, in get_values
    out = self._get_values_from_table(fields, filters, doctype, as_dict, debug, order_by, update)
  File "/home/anil/medley/apps/frappe/frappe/database/database.py", line 590, in _get_values_from_table
    r = self.sql("select {0} from `tab{1}` {2} {3} {4}"
  File "/home/anil/medley/apps/frappe/frappe/database/database.py", line 156, in sql
    self._cursor.execute(query, values)
  File "/home/anil/medley/env/lib/python3.8/site-packages/pymysql/cursors.py", line 170, in execute
    result = self._query(query)
  File "/home/anil/medley/env/lib/python3.8/site-packages/pymysql/cursors.py", line 328, in _query
    conn.query(q)
  File "/home/anil/medley/env/lib/python3.8/site-packages/pymysql/connections.py", line 517, in query
    self._affected_rows = self._read_query_result(unbuffered=unbuffered)
  File "/home/anil/medley/env/lib/python3.8/site-packages/pymysql/connections.py", line 732, in _read_query_result
    result.read()
  File "/home/anil/medley/env/lib/python3.8/site-packages/pymysql/connections.py", line 1075, in read
    first_packet = self.connection._read_packet()
  File "/home/anil/medley/env/lib/python3.8/site-packages/pymysql/connections.py", line 684, in _read_packet
    packet.check_error()
  File "/home/anil/medley/env/lib/python3.8/site-packages/pymysql/protocol.py", line 220, in check_error
    err.raise_mysql_exception(self._data)
  File "/home/anil/medley/env/lib/python3.8/site-packages/pymysql/err.py", line 109, in raise_mysql_exception
    raise errorclass(errno, errval)
pymysql.err.InternalError: (1054, "Unknown column 'gst_category' in 'field list'")
[ERROR] 2020-11-13 19:38:38,987 | /home/anil/medley/apps/frappe/frappe/utils/error.py:
New Exception collected with id: 2020-11-13 19:38:38.979816-127.0.0.1-4fd
[ERROR] 2020-11-13 19:38:51,159 | /home/anil/medley/apps/frappe/frappe/app.py:
Site: ordermedicines
Form Dict: {
 "cmd": "erpnext.regional.india.utils.get_regional_address_details",
 "company": "Medley",
 "doctype": "Sales Invoice",
 "party_details": "{\"shipping_address\":\"\",\"shipping_address_name\":\"\",\"customer_address\":\"\",\"customer\":\"\"}",
 "return_taxes": "1"
}
Request Error
Traceback (most recent call last):
  File "/home/anil/medley/apps/frappe/frappe/app.py", line 64, in application
    response = frappe.api.handle()
  File "/home/anil/medley/apps/frappe/frappe/api.py", line 59, in handle
    return frappe.handler.handle()
  File "/home/anil/medley/apps/frappe/frappe/handler.py", line 24, in handle
    data = execute_cmd(cmd)
  File "/home/anil/medley/apps/frappe/frappe/handler.py", line 64, in execute_cmd
    return frappe.call(method, **frappe.form_dict)
  File "/home/anil/medley/apps/frappe/frappe/__init__.py", line 1064, in call
    return fn(*args, **newargs)
  File "/home/anil/medley/apps/erpnext/erpnext/regional/india/utils.py", line 162, in get_regional_address_details
    get_tax_template_for_sez(party_details, master_doctype, company, 'Customer')
  File "/home/anil/medley/apps/erpnext/erpnext/regional/india/utils.py", line 229, in get_tax_template_for_sez
    gst_details = frappe.db.get_value(party_type, {'name': party_details.get(frappe.scrub(party_type))},
  File "/home/anil/medley/apps/frappe/frappe/database/database.py", line 400, in get_value
    ret = self.get_values(doctype, filters, fieldname, ignore, as_dict, debug,
  File "/home/anil/medley/apps/frappe/frappe/database/database.py", line 445, in get_values
    out = self._get_values_from_table(fields, filters, doctype, as_dict, debug, order_by, update)
  File "/home/anil/medley/apps/frappe/frappe/database/database.py", line 590, in _get_values_from_table
    r = self.sql("select {0} from `tab{1}` {2} {3} {4}"
  File "/home/anil/medley/apps/frappe/frappe/database/database.py", line 156, in sql
    self._cursor.execute(query, values)
  File "/home/anil/medley/env/lib/python3.8/site-packages/pymysql/cursors.py", line 170, in execute
    result = self._query(query)
  File "/home/anil/medley/env/lib/python3.8/site-packages/pymysql/cursors.py", line 328, in _query
    conn.query(q)
  File "/home/anil/medley/env/lib/python3.8/site-packages/pymysql/connections.py", line 517, in query
    self._affected_rows = self._read_query_result(unbuffered=unbuffered)
  File "/home/anil/medley/env/lib/python3.8/site-packages/pymysql/connections.py", line 732, in _read_query_result
    result.read()
  File "/home/anil/medley/env/lib/python3.8/site-packages/pymysql/connections.py", line 1075, in read
    first_packet = self.connection._read_packet()
  File "/home/anil/medley/env/lib/python3.8/site-packages/pymysql/connections.py", line 684, in _read_packet
    packet.check_error()
  File "/home/anil/medley/env/lib/python3.8/site-packages/pymysql/protocol.py", line 220, in check_error
    err.raise_mysql_exception(self._data)
  File "/home/anil/medley/env/lib/python3.8/site-packages/pymysql/err.py", line 109, in raise_mysql_exception
    raise errorclass(errno, errval)
pymysql.err.InternalError: (1054, "Unknown column 'gst_category' in 'field list'")
[ERROR] 2020-11-13 19:38:51,167 | /home/anil/medley/apps/frappe/frappe/utils/error.py:
New Exception collected with id: 2020-11-13 19:38:51.159919-127.0.0.1-bd6
[DEBUG] 2020-11-13 19:39:03,780 | /home/anil/medley/apps/frappe/frappe/utils/scheduler.py:
Site: ordermedicine
Access denied for site ordermedicine
[DEBUG] 2020-11-13 19:39:03,941 | /home/anil/medley/apps/frappe/frappe/utils/scheduler.py:
Site: ordermedicines
Queued events for site ordermedicines
[ERROR] 2020-11-13 19:39:23,819 | /home/anil/medley/apps/frappe/frappe/app.py:
Site: ordermedicines
Form Dict: {
 "cmd": "erpnext.regional.india.utils.get_regional_address_details",
 "company": "Medley",
 "doctype": "Sales Invoice",
 "party_details": "{\"shipping_address\":\"\",\"shipping_address_name\":\"\",\"customer_address\":\"\",\"customer\":\"\"}",
 "return_taxes": "1"
}
Request Error
Traceback (most recent call last):
  File "/home/anil/medley/apps/frappe/frappe/app.py", line 64, in application
    response = frappe.api.handle()
  File "/home/anil/medley/apps/frappe/frappe/api.py", line 59, in handle
    return frappe.handler.handle()
  File "/home/anil/medley/apps/frappe/frappe/handler.py", line 24, in handle
    data = execute_cmd(cmd)
  File "/home/anil/medley/apps/frappe/frappe/handler.py", line 64, in execute_cmd
    return frappe.call(method, **frappe.form_dict)
  File "/home/anil/medley/apps/frappe/frappe/__init__.py", line 1064, in call
    return fn(*args, **newargs)
  File "/home/anil/medley/apps/erpnext/erpnext/regional/india/utils.py", line 162, in get_regional_address_details
    get_tax_template_for_sez(party_details, master_doctype, company, 'Customer')
  File "/home/anil/medley/apps/erpnext/erpnext/regional/india/utils.py", line 229, in get_tax_template_for_sez
    gst_details = frappe.db.get_value(party_type, {'name': party_details.get(frappe.scrub(party_type))},
  File "/home/anil/medley/apps/frappe/frappe/database/database.py", line 400, in get_value
    ret = self.get_values(doctype, filters, fieldname, ignore, as_dict, debug,
  File "/home/anil/medley/apps/frappe/frappe/database/database.py", line 445, in get_values
    out = self._get_values_from_table(fields, filters, doctype, as_dict, debug, order_by, update)
  File "/home/anil/medley/apps/frappe/frappe/database/database.py", line 590, in _get_values_from_table
    r = self.sql("select {0} from `tab{1}` {2} {3} {4}"
  File "/home/anil/medley/apps/frappe/frappe/database/database.py", line 156, in sql
    self._cursor.execute(query, values)
  File "/home/anil/medley/env/lib/python3.8/site-packages/pymysql/cursors.py", line 170, in execute
    result = self._query(query)
  File "/home/anil/medley/env/lib/python3.8/site-packages/pymysql/cursors.py", line 328, in _query
    conn.query(q)
  File "/home/anil/medley/env/lib/python3.8/site-packages/pymysql/connections.py", line 517, in query
    self._affected_rows = self._read_query_result(unbuffered=unbuffered)
  File "/home/anil/medley/env/lib/python3.8/site-packages/pymysql/connections.py", line 732, in _read_query_result
    result.read()
  File "/home/anil/medley/env/lib/python3.8/site-packages/pymysql/connections.py", line 1075, in read
    first_packet = self.connection._read_packet()
  File "/home/anil/medley/env/lib/python3.8/site-packages/pymysql/connections.py", line 684, in _read_packet
    packet.check_error()
  File "/home/anil/medley/env/lib/python3.8/site-packages/pymysql/protocol.py", line 220, in check_error
    err.raise_mysql_exception(self._data)
  File "/home/anil/medley/env/lib/python3.8/site-packages/pymysql/err.py", line 109, in raise_mysql_exception
    raise errorclass(errno, errval)
pymysql.err.InternalError: (1054, "Unknown column 'gst_category' in 'field list'")
[ERROR] 2020-11-13 19:39:23,825 | /home/anil/medley/apps/frappe/frappe/utils/error.py:
New Exception collected with id: 2020-11-13 19:39:23.820277-127.0.0.1-aa7
[ERROR] 2020-11-13 19:39:36,471 | /home/anil/medley/apps/frappe/frappe/app.py:
Site: ordermedicines
Form Dict: {
 "cmd": "erpnext.regional.india.utils.get_regional_address_details",
 "company": "Medley",
 "doctype": "Sales Invoice",
 "party_details": "{\"shipping_address\":\"\",\"shipping_address_name\":\"\",\"customer_address\":\"\",\"customer\":\"\"}",
 "return_taxes": "1"
}
Request Error
Traceback (most recent call last):
  File "/home/anil/medley/apps/frappe/frappe/app.py", line 64, in application
    response = frappe.api.handle()
  File "/home/anil/medley/apps/frappe/frappe/api.py", line 59, in handle
    return frappe.handler.handle()
  File "/home/anil/medley/apps/frappe/frappe/handler.py", line 24, in handle
    data = execute_cmd(cmd)
  File "/home/anil/medley/apps/frappe/frappe/handler.py", line 64, in execute_cmd
    return frappe.call(method, **frappe.form_dict)
  File "/home/anil/medley/apps/frappe/frappe/__init__.py", line 1064, in call
    return fn(*args, **newargs)
  File "/home/anil/medley/apps/erpnext/erpnext/regional/india/utils.py", line 162, in get_regional_address_details
    get_tax_template_for_sez(party_details, master_doctype, company, 'Customer')
  File "/home/anil/medley/apps/erpnext/erpnext/regional/india/utils.py", line 229, in get_tax_template_for_sez
    gst_details = frappe.db.get_value(party_type, {'name': party_details.get(frappe.scrub(party_type))},
  File "/home/anil/medley/apps/frappe/frappe/database/database.py", line 400, in get_value
    ret = self.get_values(doctype, filters, fieldname, ignore, as_dict, debug,
  File "/home/anil/medley/apps/frappe/frappe/database/database.py", line 445, in get_values
    out = self._get_values_from_table(fields, filters, doctype, as_dict, debug, order_by, update)
  File "/home/anil/medley/apps/frappe/frappe/database/database.py", line 590, in _get_values_from_table
    r = self.sql("select {0} from `tab{1}` {2} {3} {4}"
  File "/home/anil/medley/apps/frappe/frappe/database/database.py", line 156, in sql
    self._cursor.execute(query, values)
  File "/home/anil/medley/env/lib/python3.8/site-packages/pymysql/cursors.py", line 170, in execute
    result = self._query(query)
  File "/home/anil/medley/env/lib/python3.8/site-packages/pymysql/cursors.py", line 328, in _query
    conn.query(q)
  File "/home/anil/medley/env/lib/python3.8/site-packages/pymysql/connections.py", line 517, in query
    self._affected_rows = self._read_query_result(unbuffered=unbuffered)
  File "/home/anil/medley/env/lib/python3.8/site-packages/pymysql/connections.py", line 732, in _read_query_result
    result.read()
  File "/home/anil/medley/env/lib/python3.8/site-packages/pymysql/connections.py", line 1075, in read
    first_packet = self.connection._read_packet()
  File "/home/anil/medley/env/lib/python3.8/site-packages/pymysql/connections.py", line 684, in _read_packet
    packet.check_error()
  File "/home/anil/medley/env/lib/python3.8/site-packages/pymysql/protocol.py", line 220, in check_error
    err.raise_mysql_exception(self._data)
  File "/home/anil/medley/env/lib/python3.8/site-packages/pymysql/err.py", line 109, in raise_mysql_exception
    raise errorclass(errno, errval)
pymysql.err.InternalError: (1054, "Unknown column 'gst_category' in 'field list'")
[ERROR] 2020-11-13 19:39:36,479 | /home/anil/medley/apps/frappe/frappe/utils/error.py:
New Exception collected with id: 2020-11-13 19:39:36.471939-127.0.0.1-9f5
[ERROR] 2020-11-13 19:39:52,331 | /home/anil/medley/apps/frappe/frappe/app.py:
Site: ordermedicines
Form Dict: {
 "cmd": "erpnext.regional.india.utils.get_regional_address_details",
 "company": "Medley",
 "doctype": "Sales Invoice",
 "party_details": "{\"shipping_address\":\"\",\"shipping_address_name\":\"\",\"customer_address\":\"\",\"customer\":\"\"}",
 "return_taxes": "1"
}
Request Error
Traceback (most recent call last):
  File "/home/anil/medley/apps/frappe/frappe/app.py", line 64, in application
    response = frappe.api.handle()
  File "/home/anil/medley/apps/frappe/frappe/api.py", line 59, in handle
    return frappe.handler.handle()
  File "/home/anil/medley/apps/frappe/frappe/handler.py", line 24, in handle
    data = execute_cmd(cmd)
  File "/home/anil/medley/apps/frappe/frappe/handler.py", line 64, in execute_cmd
    return frappe.call(method, **frappe.form_dict)
  File "/home/anil/medley/apps/frappe/frappe/__init__.py", line 1064, in call
    return fn(*args, **newargs)
  File "/home/anil/medley/apps/erpnext/erpnext/regional/india/utils.py", line 162, in get_regional_address_details
    get_tax_template_for_sez(party_details, master_doctype, company, 'Customer')
  File "/home/anil/medley/apps/erpnext/erpnext/regional/india/utils.py", line 229, in get_tax_template_for_sez
    gst_details = frappe.db.get_value(party_type, {'name': party_details.get(frappe.scrub(party_type))},
  File "/home/anil/medley/apps/frappe/frappe/database/database.py", line 400, in get_value
    ret = self.get_values(doctype, filters, fieldname, ignore, as_dict, debug,
  File "/home/anil/medley/apps/frappe/frappe/database/database.py", line 445, in get_values
    out = self._get_values_from_table(fields, filters, doctype, as_dict, debug, order_by, update)
  File "/home/anil/medley/apps/frappe/frappe/database/database.py", line 590, in _get_values_from_table
    r = self.sql("select {0} from `tab{1}` {2} {3} {4}"
  File "/home/anil/medley/apps/frappe/frappe/database/database.py", line 156, in sql
    self._cursor.execute(query, values)
  File "/home/anil/medley/env/lib/python3.8/site-packages/pymysql/cursors.py", line 170, in execute
    result = self._query(query)
  File "/home/anil/medley/env/lib/python3.8/site-packages/pymysql/cursors.py", line 328, in _query
    conn.query(q)
  File "/home/anil/medley/env/lib/python3.8/site-packages/pymysql/connections.py", line 517, in query
    self._affected_rows = self._read_query_result(unbuffered=unbuffered)
  File "/home/anil/medley/env/lib/python3.8/site-packages/pymysql/connections.py", line 732, in _read_query_result
    result.read()
  File "/home/anil/medley/env/lib/python3.8/site-packages/pymysql/connections.py", line 1075, in read
    first_packet = self.connection._read_packet()
  File "/home/anil/medley/env/lib/python3.8/site-packages/pymysql/connections.py", line 684, in _read_packet
    packet.check_error()
  File "/home/anil/medley/env/lib/python3.8/site-packages/pymysql/protocol.py", line 220, in check_error
    err.raise_mysql_exception(self._data)
  File "/home/anil/medley/env/lib/python3.8/site-packages/pymysql/err.py", line 109, in raise_mysql_exception
    raise errorclass(errno, errval)
pymysql.err.InternalError: (1054, "Unknown column 'gst_category' in 'field list'")
[ERROR] 2020-11-13 19:39:52,337 | /home/anil/medley/apps/frappe/frappe/utils/error.py:
New Exception collected with id: 2020-11-13 19:39:52.331955-127.0.0.1-b9c
[DEBUG] 2020-11-13 19:40:04,021 | /home/anil/medley/apps/frappe/frappe/utils/scheduler.py:
Site: ordermedicine
Access denied for site ordermedicine
[DEBUG] 2020-11-13 19:40:04,270 | /home/anil/medley/apps/frappe/frappe/utils/scheduler.py:
Site: ordermedicines
Queued events for site ordermedicines
[DEBUG] 2020-11-13 19:41:04,332 | /home/anil/medley/apps/frappe/frappe/utils/scheduler.py:
Site: ordermedicine
Access denied for site ordermedicine
[DEBUG] 2020-11-13 19:41:04,496 | /home/anil/medley/apps/frappe/frappe/utils/scheduler.py:
Site: ordermedicines
Queued events for site ordermedicines
[ERROR] 2020-11-13 19:41:15,677 | /home/anil/medley/apps/frappe/frappe/app.py:
Site: ordermedicines
Form Dict: {
 "cmd": "erpnext.regional.india.utils.get_regional_address_details",
 "company": "Medley",
 "doctype": "Sales Invoice",
 "party_details": "{\"shipping_address\":\"\",\"shipping_address_name\":\"\",\"customer_address\":\"\",\"customer\":\"\"}",
 "return_taxes": "1"
}
Request Error
Traceback (most recent call last):
  File "/home/anil/medley/apps/frappe/frappe/app.py", line 64, in application
    response = frappe.api.handle()
  File "/home/anil/medley/apps/frappe/frappe/api.py", line 59, in handle
    return frappe.handler.handle()
  File "/home/anil/medley/apps/frappe/frappe/handler.py", line 24, in handle
    data = execute_cmd(cmd)
  File "/home/anil/medley/apps/frappe/frappe/handler.py", line 64, in execute_cmd
    return frappe.call(method, **frappe.form_dict)
  File "/home/anil/medley/apps/frappe/frappe/__init__.py", line 1064, in call
    return fn(*args, **newargs)
  File "/home/anil/medley/apps/erpnext/erpnext/regional/india/utils.py", line 162, in get_regional_address_details
    get_tax_template_for_sez(party_details, master_doctype, company, 'Customer')
  File "/home/anil/medley/apps/erpnext/erpnext/regional/india/utils.py", line 229, in get_tax_template_for_sez
    gst_details = frappe.db.get_value(party_type, {'name': party_details.get(frappe.scrub(party_type))},
  File "/home/anil/medley/apps/frappe/frappe/database/database.py", line 400, in get_value
    ret = self.get_values(doctype, filters, fieldname, ignore, as_dict, debug,
  File "/home/anil/medley/apps/frappe/frappe/database/database.py", line 445, in get_values
    out = self._get_values_from_table(fields, filters, doctype, as_dict, debug, order_by, update)
  File "/home/anil/medley/apps/frappe/frappe/database/database.py", line 590, in _get_values_from_table
    r = self.sql("select {0} from `tab{1}` {2} {3} {4}"
  File "/home/anil/medley/apps/frappe/frappe/database/database.py", line 156, in sql
    self._cursor.execute(query, values)
  File "/home/anil/medley/env/lib/python3.8/site-packages/pymysql/cursors.py", line 170, in execute
    result = self._query(query)
  File "/home/anil/medley/env/lib/python3.8/site-packages/pymysql/cursors.py", line 328, in _query
    conn.query(q)
  File "/home/anil/medley/env/lib/python3.8/site-packages/pymysql/connections.py", line 517, in query
    self._affected_rows = self._read_query_result(unbuffered=unbuffered)
  File "/home/anil/medley/env/lib/python3.8/site-packages/pymysql/connections.py", line 732, in _read_query_result
    result.read()
  File "/home/anil/medley/env/lib/python3.8/site-packages/pymysql/connections.py", line 1075, in read
    first_packet = self.connection._read_packet()
  File "/home/anil/medley/env/lib/python3.8/site-packages/pymysql/connections.py", line 684, in _read_packet
    packet.check_error()
  File "/home/anil/medley/env/lib/python3.8/site-packages/pymysql/protocol.py", line 220, in check_error
    err.raise_mysql_exception(self._data)
  File "/home/anil/medley/env/lib/python3.8/site-packages/pymysql/err.py", line 109, in raise_mysql_exception
    raise errorclass(errno, errval)
pymysql.err.InternalError: (1054, "Unknown column 'gst_category' in 'field list'")
[ERROR] 2020-11-13 19:41:15,684 | /home/anil/medley/apps/frappe/frappe/utils/error.py:
New Exception collected with id: 2020-11-13 19:41:15.678045-127.0.0.1-27b
[ERROR] 2020-11-13 19:41:23,736 | /home/anil/medley/apps/frappe/frappe/app.py:
Site: ordermedicines
Form Dict: {
 "cmd": "erpnext.regional.india.utils.get_regional_address_details",
 "company": "Medley",
 "doctype": "Sales Invoice",
 "party_details": "{\"shipping_address\":\"\",\"shipping_address_name\":\"\",\"customer_address\":\"\",\"customer\":\"\"}",
 "return_taxes": "1"
}
Request Error
Traceback (most recent call last):
  File "/home/anil/medley/apps/frappe/frappe/app.py", line 64, in application
    response = frappe.api.handle()
  File "/home/anil/medley/apps/frappe/frappe/api.py", line 59, in handle
    return frappe.handler.handle()
  File "/home/anil/medley/apps/frappe/frappe/handler.py", line 24, in handle
    data = execute_cmd(cmd)
  File "/home/anil/medley/apps/frappe/frappe/handler.py", line 64, in execute_cmd
    return frappe.call(method, **frappe.form_dict)
  File "/home/anil/medley/apps/frappe/frappe/__init__.py", line 1064, in call
    return fn(*args, **newargs)
  File "/home/anil/medley/apps/erpnext/erpnext/regional/india/utils.py", line 162, in get_regional_address_details
    get_tax_template_for_sez(party_details, master_doctype, company, 'Customer')
  File "/home/anil/medley/apps/erpnext/erpnext/regional/india/utils.py", line 229, in get_tax_template_for_sez
    gst_details = frappe.db.get_value(party_type, {'name': party_details.get(frappe.scrub(party_type))},
  File "/home/anil/medley/apps/frappe/frappe/database/database.py", line 400, in get_value
    ret = self.get_values(doctype, filters, fieldname, ignore, as_dict, debug,
  File "/home/anil/medley/apps/frappe/frappe/database/database.py", line 445, in get_values
    out = self._get_values_from_table(fields, filters, doctype, as_dict, debug, order_by, update)
  File "/home/anil/medley/apps/frappe/frappe/database/database.py", line 590, in _get_values_from_table
    r = self.sql("select {0} from `tab{1}` {2} {3} {4}"
  File "/home/anil/medley/apps/frappe/frappe/database/database.py", line 156, in sql
    self._cursor.execute(query, values)
  File "/home/anil/medley/env/lib/python3.8/site-packages/pymysql/cursors.py", line 170, in execute
    result = self._query(query)
  File "/home/anil/medley/env/lib/python3.8/site-packages/pymysql/cursors.py", line 328, in _query
    conn.query(q)
  File "/home/anil/medley/env/lib/python3.8/site-packages/pymysql/connections.py", line 517, in query
    self._affected_rows = self._read_query_result(unbuffered=unbuffered)
  File "/home/anil/medley/env/lib/python3.8/site-packages/pymysql/connections.py", line 732, in _read_query_result
    result.read()
  File "/home/anil/medley/env/lib/python3.8/site-packages/pymysql/connections.py", line 1075, in read
    first_packet = self.connection._read_packet()
  File "/home/anil/medley/env/lib/python3.8/site-packages/pymysql/connections.py", line 684, in _read_packet
    packet.check_error()
  File "/home/anil/medley/env/lib/python3.8/site-packages/pymysql/protocol.py", line 220, in check_error
    err.raise_mysql_exception(self._data)
  File "/home/anil/medley/env/lib/python3.8/site-packages/pymysql/err.py", line 109, in raise_mysql_exception
    raise errorclass(errno, errval)
pymysql.err.InternalError: (1054, "Unknown column 'gst_category' in 'field list'")
[ERROR] 2020-11-13 19:41:23,742 | /home/anil/medley/apps/frappe/frappe/utils/error.py:
New Exception collected with id: 2020-11-13 19:41:23.737356-127.0.0.1-ad6
[DEBUG] 2020-11-13 19:42:04,588 | /home/anil/medley/apps/frappe/frappe/utils/scheduler.py:
Site: ordermedicine
Access denied for site ordermedicine
[DEBUG] 2020-11-13 19:42:05,078 | /home/anil/medley/apps/frappe/frappe/utils/scheduler.py:
Site: ordermedicines
Queued events for site ordermedicines
[ERROR] 2020-11-13 19:43:10,872 | /home/anil/medley/apps/frappe/frappe/app.py:
Site: ordermedicines
Form Dict: {
 "cmd": "frappe.realtime.get_user_info"
}
Request Error
Traceback (most recent call last):
  File "/home/anil/medley/apps/frappe/frappe/app.py", line 64, in application
    response = frappe.api.handle()
  File "/home/anil/medley/apps/frappe/frappe/api.py", line 59, in handle
    return frappe.handler.handle()
  File "/home/anil/medley/apps/frappe/frappe/handler.py", line 24, in handle
    data = execute_cmd(cmd)
  File "/home/anil/medley/apps/frappe/frappe/handler.py", line 64, in execute_cmd
    return frappe.call(method, **frappe.form_dict)
  File "/home/anil/medley/apps/frappe/frappe/__init__.py", line 1064, in call
    return fn(*args, **newargs)
TypeError: get_user_info() missing 1 required positional argument: 'sid'
[ERROR] 2020-11-13 19:43:10,872 | /home/anil/medley/apps/frappe/frappe/app.py:
Site: ordermedicines
Form Dict: {
 "cmd": "frappe.realtime.get_user_info"
}
Site: ordermedicines
Form Dict: {
 "cmd": "frappe.realtime.get_user_info"
}
Request Error
Traceback (most recent call last):
  File "/home/anil/medley/apps/frappe/frappe/app.py", line 64, in application
    response = frappe.api.handle()
  File "/home/anil/medley/apps/frappe/frappe/api.py", line 59, in handle
    return frappe.handler.handle()
  File "/home/anil/medley/apps/frappe/frappe/handler.py", line 24, in handle
    data = execute_cmd(cmd)
  File "/home/anil/medley/apps/frappe/frappe/handler.py", line 64, in execute_cmd
    return frappe.call(method, **frappe.form_dict)
  File "/home/anil/medley/apps/frappe/frappe/__init__.py", line 1064, in call
    return fn(*args, **newargs)
TypeError: get_user_info() missing 1 required positional argument: 'sid'
[ERROR] 2020-11-13 19:43:10,872 | /home/anil/medley/apps/frappe/frappe/app.py:
Site: ordermedicines
Form Dict: {
 "cmd": "frappe.realtime.get_user_info"
}
Request Error
Traceback (most recent call last):
  File "/home/anil/medley/apps/frappe/frappe/app.py", line 64, in application
    response = frappe.api.handle()
  File "/home/anil/medley/apps/frappe/frappe/api.py", line 59, in handle
    return frappe.handler.handle()
  File "/home/anil/medley/apps/frappe/frappe/handler.py", line 24, in handle
    data = execute_cmd(cmd)
  File "/home/anil/medley/apps/frappe/frappe/handler.py", line 64, in execute_cmd
    return frappe.call(method, **frappe.form_dict)
  File "/home/anil/medley/apps/frappe/frappe/__init__.py", line 1064, in call
    return fn(*args, **newargs)
TypeError: get_user_info() missing 1 required positional argument: 'sid'
[ERROR] 2020-11-13 19:43:10,872 | /home/anil/medley/apps/frappe/frappe/app.py:
Site: ordermedicines
Form Dict: {
 "cmd": "frappe.realtime.get_user_info"
}
Site: ordermedicines
Form Dict: {
 "cmd": "frappe.realtime.get_user_info"
}
Request Error
Traceback (most recent call last):
  File "/home/anil/medley/apps/frappe/frappe/app.py", line 64, in application
    response = frappe.api.handle()
  File "/home/anil/medley/apps/frappe/frappe/api.py", line 59, in handle
    return frappe.handler.handle()
  File "/home/anil/medley/apps/frappe/frappe/handler.py", line 24, in handle
    data = execute_cmd(cmd)
  File "/home/anil/medley/apps/frappe/frappe/handler.py", line 64, in execute_cmd
    return frappe.call(method, **frappe.form_dict)
  File "/home/anil/medley/apps/frappe/frappe/__init__.py", line 1064, in call
    return fn(*args, **newargs)
TypeError: get_user_info() missing 1 required positional argument: 'sid'
[ERROR] 2020-11-13 19:43:11,133 | /home/anil/medley/apps/frappe/frappe/utils/error.py:
New Exception collected with id: 2020-11-13 19:43:10.873670-127.0.0.1-9f0
[ERROR] 2020-11-13 19:43:11,134 | /home/anil/medley/apps/frappe/frappe/utils/error.py:
New Exception collected with id: 2020-11-13 19:43:10.874129-127.0.0.1-451
[DEBUG] 2020-11-13 19:44:23,080 | /home/anil/medley/apps/frappe/frappe/utils/scheduler.py:
Site: ordermedicine
Access denied for site ordermedicine
[DEBUG] 2020-11-13 19:44:53,039 | /home/anil/medley/apps/frappe/frappe/utils/scheduler.py:
Site: ordermedicines
Queued events for site ordermedicines
[DEBUG] 2020-11-16 07:50:58,568 | /home/anil/medley/apps/frappe/frappe/utils/scheduler.py:
Site: ordermedicine
Access denied for site ordermedicine
[DEBUG] 2020-11-16 07:50:58,810 | /home/anil/medley/apps/frappe/frappe/utils/scheduler.py:
Site: ordermedicines
Queued events for site ordermedicines
[DEBUG] 2020-11-16 07:51:58,883 | /home/anil/medley/apps/frappe/frappe/utils/scheduler.py:
Site: ordermedicine
Access denied for site ordermedicine
[ERROR] 2020-11-16 07:54:17,922 | /home/anil/medley/apps/frappe/frappe/app.py:
Site: ordermedicines
Form Dict: {
 "cmd": "frappe.realtime.get_user_info"
}
Request Error
Traceback (most recent call last):
  File "/home/anil/medley/apps/frappe/frappe/app.py", line 64, in application
    response = frappe.api.handle()
  File "/home/anil/medley/apps/frappe/frappe/api.py", line 59, in handle
    return frappe.handler.handle()
  File "/home/anil/medley/apps/frappe/frappe/handler.py", line 24, in handle
    data = execute_cmd(cmd)
  File "/home/anil/medley/apps/frappe/frappe/handler.py", line 64, in execute_cmd
    return frappe.call(method, **frappe.form_dict)
  File "/home/anil/medley/apps/frappe/frappe/__init__.py", line 1064, in call
    return fn(*args, **newargs)
TypeError: get_user_info() missing 1 required positional argument: 'sid'
[ERROR] 2020-11-16 07:54:18,197 | /home/anil/medley/apps/frappe/frappe/utils/error.py:
New Exception collected with id: 2020-11-16 07:54:17.922732-127.0.0.1-6cb
[DEBUG] 2020-11-16 07:55:16,327 | /home/anil/medley/apps/frappe/frappe/utils/scheduler.py:
Site: ordermedicine
Access denied for site ordermedicine
[DEBUG] 2020-11-16 07:55:16,495 | /home/anil/medley/apps/frappe/frappe/utils/scheduler.py:
Site: ordermedicines
Queued events for site ordermedicines
[DEBUG] 2020-11-16 07:56:16,563 | /home/anil/medley/apps/frappe/frappe/utils/scheduler.py:
Site: ordermedicine
Access denied for site ordermedicine
[DEBUG] 2020-11-16 07:56:16,771 | /home/anil/medley/apps/frappe/frappe/utils/scheduler.py:
Site: ordermedicines
Queued events for site ordermedicines
[DEBUG] 2020-11-16 07:57:16,853 | /home/anil/medley/apps/frappe/frappe/utils/scheduler.py:
Site: ordermedicine
Access denied for site ordermedicine
[DEBUG] 2020-11-16 07:57:16,985 | /home/anil/medley/apps/frappe/frappe/utils/scheduler.py:
Site: ordermedicines
Queued events for site ordermedicines
[DEBUG] 2020-11-16 07:58:17,073 | /home/anil/medley/apps/frappe/frappe/utils/scheduler.py:
Site: ordermedicine
Access denied for site ordermedicine
[DEBUG] 2020-11-16 07:58:17,189 | /home/anil/medley/apps/frappe/frappe/utils/scheduler.py:
Site: ordermedicines
Queued events for site ordermedicines
[DEBUG] 2020-11-16 07:59:17,271 | /home/anil/medley/apps/frappe/frappe/utils/scheduler.py:
Site: ordermedicine
Access denied for site ordermedicine
[DEBUG] 2020-11-16 07:59:17,437 | /home/anil/medley/apps/frappe/frappe/utils/scheduler.py:
Site: ordermedicines
Queued events for site ordermedicines
[DEBUG] 2020-11-16 08:00:17,519 | /home/anil/medley/apps/frappe/frappe/utils/scheduler.py:
Site: ordermedicine
Access denied for site ordermedicine
[DEBUG] 2020-11-16 08:00:17,686 | /home/anil/medley/apps/frappe/frappe/utils/scheduler.py:
Site: ordermedicines
Queued events for site ordermedicines
[DEBUG] 2020-11-16 08:01:17,774 | /home/anil/medley/apps/frappe/frappe/utils/scheduler.py:
Site: ordermedicine
Access denied for site ordermedicine
[DEBUG] 2020-11-16 08:01:17,899 | /home/anil/medley/apps/frappe/frappe/utils/scheduler.py:
Site: ordermedicines
Queued events for site ordermedicines
[DEBUG] 2020-11-16 08:02:17,979 | /home/anil/medley/apps/frappe/frappe/utils/scheduler.py:
Site: ordermedicine
Access denied for site ordermedicine
[DEBUG] 2020-11-16 08:02:18,082 | /home/anil/medley/apps/frappe/frappe/utils/scheduler.py:
Site: ordermedicines
Queued events for site ordermedicines
[DEBUG] 2020-11-16 08:03:18,160 | /home/anil/medley/apps/frappe/frappe/utils/scheduler.py:
Site: ordermedicine
Access denied for site ordermedicine
[DEBUG] 2020-11-16 08:03:18,263 | /home/anil/medley/apps/frappe/frappe/utils/scheduler.py:
Site: ordermedicines
Queued events for site ordermedicines
[DEBUG] 2020-11-16 08:04:18,349 | /home/anil/medley/apps/frappe/frappe/utils/scheduler.py:
Site: ordermedicine
Access denied for site ordermedicine
[DEBUG] 2020-11-16 08:04:18,496 | /home/anil/medley/apps/frappe/frappe/utils/scheduler.py:
Site: ordermedicines
Queued events for site ordermedicines
[DEBUG] 2020-11-16 08:05:18,583 | /home/anil/medley/apps/frappe/frappe/utils/scheduler.py:
Site: ordermedicine
Access denied for site ordermedicine
[DEBUG] 2020-11-16 08:05:18,709 | /home/anil/medley/apps/frappe/frappe/utils/scheduler.py:
Site: ordermedicines
Queued events for site ordermedicines
[DEBUG] 2020-11-16 08:06:18,785 | /home/anil/medley/apps/frappe/frappe/utils/scheduler.py:
Site: ordermedicine
Access denied for site ordermedicine
[DEBUG] 2020-11-16 08:06:18,878 | /home/anil/medley/apps/frappe/frappe/utils/scheduler.py:
Site: ordermedicines
Queued events for site ordermedicines
[DEBUG] 2020-11-16 08:07:18,951 | /home/anil/medley/apps/frappe/frappe/utils/scheduler.py:
Site: ordermedicine
Access denied for site ordermedicine
[DEBUG] 2020-11-16 08:07:19,059 | /home/anil/medley/apps/frappe/frappe/utils/scheduler.py:
Site: ordermedicines
Queued events for site ordermedicines
[DEBUG] 2020-11-16 08:08:19,128 | /home/anil/medley/apps/frappe/frappe/utils/scheduler.py:
Site: ordermedicine
Access denied for site ordermedicine
[DEBUG] 2020-11-16 08:08:19,281 | /home/anil/medley/apps/frappe/frappe/utils/scheduler.py:
Site: ordermedicines
Queued events for site ordermedicines
[DEBUG] 2020-11-16 08:09:19,352 | /home/anil/medley/apps/frappe/frappe/utils/scheduler.py:
Site: ordermedicine
Access denied for site ordermedicine
[DEBUG] 2020-11-16 08:09:19,506 | /home/anil/medley/apps/frappe/frappe/utils/scheduler.py:
Site: ordermedicines
Queued events for site ordermedicines
[DEBUG] 2020-11-16 08:10:19,574 | /home/anil/medley/apps/frappe/frappe/utils/scheduler.py:
Site: ordermedicine
Access denied for site ordermedicine
[DEBUG] 2020-11-16 08:10:19,696 | /home/anil/medley/apps/frappe/frappe/utils/scheduler.py:
Site: ordermedicines
Queued events for site ordermedicines
[DEBUG] 2020-11-16 08:11:19,757 | /home/anil/medley/apps/frappe/frappe/utils/scheduler.py:
Site: ordermedicine
Access denied for site ordermedicine
[DEBUG] 2020-11-16 08:11:19,853 | /home/anil/medley/apps/frappe/frappe/utils/scheduler.py:
Site: ordermedicines
Queued events for site ordermedicines
[DEBUG] 2020-11-16 08:12:19,935 | /home/anil/medley/apps/frappe/frappe/utils/scheduler.py:
Site: ordermedicine
Access denied for site ordermedicine
[DEBUG] 2020-11-16 08:12:20,121 | /home/anil/medley/apps/frappe/frappe/utils/scheduler.py:
Site: ordermedicines
Queued events for site ordermedicines
[DEBUG] 2020-11-16 08:13:20,192 | /home/anil/medley/apps/frappe/frappe/utils/scheduler.py:
Site: ordermedicine
Access denied for site ordermedicine
[DEBUG] 2020-11-16 08:13:20,330 | /home/anil/medley/apps/frappe/frappe/utils/scheduler.py:
Site: ordermedicines
Queued events for site ordermedicines
[DEBUG] 2020-11-16 08:14:20,393 | /home/anil/medley/apps/frappe/frappe/utils/scheduler.py:
Site: ordermedicine
Access denied for site ordermedicine
[DEBUG] 2020-11-16 08:14:20,545 | /home/anil/medley/apps/frappe/frappe/utils/scheduler.py:
Site: ordermedicines
Queued events for site ordermedicines
[DEBUG] 2020-11-16 08:15:20,617 | /home/anil/medley/apps/frappe/frappe/utils/scheduler.py:
Site: ordermedicine
Access denied for site ordermedicine
[DEBUG] 2020-11-16 08:15:20,776 | /home/anil/medley/apps/frappe/frappe/utils/scheduler.py:
Site: ordermedicines
Queued events for site ordermedicines
[DEBUG] 2020-11-16 08:16:20,847 | /home/anil/medley/apps/frappe/frappe/utils/scheduler.py:
Site: ordermedicine
Access denied for site ordermedicine
[DEBUG] 2020-11-16 08:16:21,004 | /home/anil/medley/apps/frappe/frappe/utils/scheduler.py:
Site: ordermedicines
Queued events for site ordermedicines
[DEBUG] 2020-11-16 08:17:21,074 | /home/anil/medley/apps/frappe/frappe/utils/scheduler.py:
Site: ordermedicine
Access denied for site ordermedicine
[DEBUG] 2020-11-16 08:17:21,186 | /home/anil/medley/apps/frappe/frappe/utils/scheduler.py:
Site: ordermedicines
Queued events for site ordermedicines
[DEBUG] 2020-11-16 08:18:21,253 | /home/anil/medley/apps/frappe/frappe/utils/scheduler.py:
Site: ordermedicine
Access denied for site ordermedicine
[DEBUG] 2020-11-16 08:18:21,384 | /home/anil/medley/apps/frappe/frappe/utils/scheduler.py:
Site: ordermedicines
Queued events for site ordermedicines
[ERROR] 2020-11-16 08:19:08,178 | /home/anil/medley/apps/frappe/frappe/app.py:
Site: ordermedicines
Form Dict: {
 "cmd": "erpnext.selling.page.point_of_sale.point_of_sale.get_items",
 "item_group": "All Item Groups",
 "page_length": "40",
 "search_value": "",
 "start": "0"
}
Request Error
Traceback (most recent call last):
  File "/home/anil/medley/apps/frappe/frappe/app.py", line 64, in application
    response = frappe.api.handle()
  File "/home/anil/medley/apps/frappe/frappe/api.py", line 59, in handle
    return frappe.handler.handle()
  File "/home/anil/medley/apps/frappe/frappe/handler.py", line 24, in handle
    data = execute_cmd(cmd)
  File "/home/anil/medley/apps/frappe/frappe/handler.py", line 64, in execute_cmd
    return frappe.call(method, **frappe.form_dict)
  File "/home/anil/medley/apps/frappe/frappe/__init__.py", line 1064, in call
    return fn(*args, **newargs)
TypeError: get_items() missing 1 required positional argument: 'price_list'
[ERROR] 2020-11-16 08:19:08,378 | /home/anil/medley/apps/frappe/frappe/utils/error.py:
New Exception collected with id: 2020-11-16 08:19:08.179185-127.0.0.1-2ce
[ERROR] 2020-11-16 08:19:09,116 | /home/anil/medley/apps/frappe/frappe/utils/error.py:
New Exception collected with id: 2020-11-16 08:19:09.100778-127.0.0.1-ff3
[DEBUG] 2020-11-16 08:19:21,462 | /home/anil/medley/apps/frappe/frappe/utils/scheduler.py:
Site: ordermedicine
Access denied for site ordermedicine
[DEBUG] 2020-11-16 08:19:21,628 | /home/anil/medley/apps/frappe/frappe/utils/scheduler.py:
Site: ordermedicines
Queued events for site ordermedicines
